Workbook

Sheet 合数一覧
B1: 月
B2: 月 | E2: 1000 | H2: 1000 | K2: 1000 | N2: 1000 | Q2: 1000 | T2: 1000
C3: 米(合) | D3: 寿司具(g) | F3: 袋数 | G3: うずら豆 | I3: 袋数 | J3: 錦糸玉子(乾燥) | L3: 袋数 | M3: さくらでんぶ | O3: 袋数 | P3: ゆず酢 | R3: 袋数 | S3: 寿司酢(g) | U3: 袋数
D4: =D$2*$C4 -> 0 | E4: =D4/E$2 -> 0 | F4: =ROUNDUP(E4,0) -> 0 | G4: =G$2*$C4 -> 0 | H4: =G4/H$2 -> 0 | I4: =ROUNDUP(H4,0) -> 0 | J4: =J$2*$C4 -> 0 | K4: =J4/K$2 -> 0 | L4: =ROUNDUP(K4,0) -> 0 | M4: =M$2*$C4 -> 0 | N4: =M4/N$2 -> 0 | O4: =ROUNDUP(N4,0) -> 0 | P4: =P$2*$C4 -> 0 | Q4: =P4/Q$2 -> 0 | R4: =ROUNDUP(Q4,0) -> 0 | S4: =S$2*$C4 -> 0 | T4: =S4/T$2 -> 0 | U4: =ROUNDUP(T4,0) -> 0
D5: =D$2*$C5 -> 0 | E5: =D5/E$2 -> 0 | F5: =ROUNDUP(E5,0) -> 0 | G5: =G$2*$C5 -> 0 | H5: =G5/H$2 -> 0 | I5: =ROUNDUP(H5,0) -> 0 | J5: =J$2*$C5 -> 0 | K5: =J5/K$2 -> 0 | L5: =ROUNDUP(K5,0) -> 0 | M5: =M$2*$C5 -> 0 | N5: =M5/N$2 -> 0 | O5: =ROUNDUP(N5,0) -> 0 | P5: =P$2*$C5 -> 0 | Q5: =P5/Q$2 -> 0 | R5: =ROUNDUP(Q5,0) -> 0 | S5: =S$2*$C5 -> 0 | T5: =S5/T$2 -> 0 | U5: =ROUNDUP(T5,0) -> 0 | Y5: 具材量補正割合 | Z5: 1
D6: =D$2*$C6 -> 0 | E6: =D6/E$2 -> 0 | F6: =ROUNDUP(E6,0) -> 0 | G6: =G$2*$C6 -> 0 | H6: =G6/H$2 -> 0 | I6: =ROUNDUP(H6,0) -> 0 | J6: =J$2*$C6 -> 0 | K6: =J6/K$2 -> 0 | L6: =ROUNDUP(K6,0) -> 0 | M6: =M$2*$C6 -> 0 | N6: =M6/N$2 -> 0 | O6: =ROUNDUP(N6,0) -> 0 | P6: =P$2*$C6 -> 0 | Q6: =P6/Q$2 -> 0 | R6: =ROUNDUP(Q6,0) -> 0 | S6: =S$2*$C6 -> 0 | T6: =S6/T$2 -> 0 | U6: =ROUNDUP(T6,0) -> 0 | W6: 寿司具 | X6: 比率 | Y6: 補正なし(g) | Z6: 補正あり(g)
D7: =D$2*$C7 -> 0 | E7: =D7/E$2 -> 0 | F7: =ROUNDUP(E7,0) -> 0 | G7: =G$2*$C7 -> 0 | H7: =G7/H$2 -> 0 | I7: =ROUNDUP(H7,0) -> 0 | J7: =J$2*$C7 -> 0 | K7: =J7/K$2 -> 0 | L7: =ROUNDUP(K7,0) -> 0 | M7: =M$2*$C7 -> 0 | N7: =M7/N$2 -> 0 | O7: =ROUNDUP(N7,0) -> 0 | P7: =P$2*$C7 -> 0 | Q7: =P7/Q$2 -> 0 | R7: =ROUNDUP(Q7,0) -> 0 | S7: =S$2*$C7 -> 0 | T7: =S7/T$2 -> 0 | U7: =ROUNDUP(T7,0) -> 0 | Y7: =IFERROR(Y$22*(X7/SUM($X$7:$X$21)), 0) -> 0 | Z7: =Y7*$Z$5 -> 0 | AB7: =IFERROR(X7/$X$22, 0) -> 0
D8: =D$2*$C8 -> 0 | E8: =D8/E$2 -> 0 | F8: =ROUNDUP(E8,0) -> 0 | G8: =G$2*$C8 -> 0 | H8: =G8/H$2 -> 0 | I8: =ROUNDUP(H8,0) -> 0 | J8: =J$2*$C8 -> 0 | K8: =J8/K$2 -> 0 | L8: =ROUNDUP(K8,0) -> 0 | M8: =M$2*$C8 -> 0 | N8: =M8/N$2 -> 0 | O8: =ROUNDUP(N8,0) -> 0 | P8: =P$2*$C8 -> 0 | Q8: =P8/Q$2 -> 0 | R8: =ROUNDUP(Q8,0) -> 0 | S8: =S$2*$C8 -> 0 | T8: =S8/T$2 -> 0 | U8: =ROUNDUP(T8,0) -> 0 | Y8: =IFERROR(Y$22*(X8/SUM($X$7:$X$21)), 0) -> 0 | Z8: =Y8*$Z$5 -> 0 | AB8: =IFERROR(X8/$X$22, 0) -> 0
D9: =D$2*$C9 -> 0 | E9: =D9/E$2 -> 0 | F9: =ROUNDUP(E9,0) -> 0 | G9: =G$2*$C9 -> 0 | H9: =G9/H$2 -> 0 | I9: =ROUNDUP(H9,0) -> 0 | J9: =J$2*$C9 -> 0 | K9: =J9/K$2 -> 0 | L9: =ROUNDUP(K9,0) -> 0 | M9: =M$2*$C9 -> 0 | N9: =M9/N$2 -> 0 | O9: =ROUNDUP(N9,0) -> 0 | P9: =P$2*$C9 -> 0 | Q9: =P9/Q$2 -> 0 | R9: =ROUNDUP(Q9,0) -> 0 | S9: =S$2*$C9 -> 0 | T9: =S9/T$2 -> 0 | U9: =ROUNDUP(T9,0) -> 0 | Y9: =IFERROR(Y$22*(X9/SUM($X$7:$X$21)), 0) -> 0 | Z9: =Y9*$Z$5 -> 0 | AB9: =IFERROR(X9/$X$22, 0) -> 0
D10: =D$2*$C10 -> 0 | E10: =D10/E$2 -> 0 | F10: =ROUNDUP(E10,0) -> 0 | G10: =G$2*$C10 -> 0 | H10: =G10/H$2 -> 0 | I10: =ROUNDUP(H10,0) -> 0 | J10: =J$2*$C10 -> 0 | K10: =J10/K$2 -> 0 | L10: =ROUNDUP(K10,0) -> 0 | M10: =M$2*$C10 -> 0 | N10: =M10/N$2 -> 0 | O10: =ROUNDUP(N10,0) -> 0 | P10: =P$2*$C10 -> 0 | Q10: =P10/Q$2 -> 0 | R10: =ROUNDUP(Q10,0) -> 0 | S10: =S$2*$C10 -> 0 | T10: =S10/T$2 -> 0 | U10: =ROUNDUP(T10,0) -> 0 | Y10: =IFERROR(Y$22*(X10/SUM($X$7:$X$21)), 0) -> 0 | Z10: =Y10*$Z$5 -> 0 | AB10: =IFERROR(X10/$X$22, 0) -> 0
D11: =D$2*$C11 -> 0 | E11: =D11/E$2 -> 0 | F11: =ROUNDUP(E11,0) -> 0 | G11: =G$2*$C11 -> 0 | H11: =G11/H$2 -> 0 | I11: =ROUNDUP(H11,0) -> 0 | J11: =J$2*$C11 -> 0 | K11: =J11/K$2 -> 0 | L11: =ROUNDUP(K11,0) -> 0 | M11: =M$2*$C11 -> 0 | N11: =M11/N$2 -> 0 | O11: =ROUNDUP(N11,0) -> 0 | P11: =P$2*$C11 -> 0 | Q11: =P11/Q$2 -> 0 | R11: =ROUNDUP(Q11,0) -> 0 | S11: =S$2*$C11 -> 0 | T11: =S11/T$2 -> 0 | U11: =ROUNDUP(T11,0) -> 0 | Y11: =IFERROR(Y$22*(X11/SUM($X$7:$X$21)), 0) -> 0 | Z11: =Y11*$Z$5 -> 0 | AB11: =IFERROR(X11/$X$22, 0) -> 0
D12: =D$2*$C12 -> 0 | E12: =D12/E$2 -> 0 | F12: =ROUNDUP(E12,0) -> 0 | G12: =G$2*$C12 -> 0 | H12: =G12/H$2 -> 0 | I12: =ROUNDUP(H12,0) -> 0 | J12: =J$2*$C12 -> 0 | K12: =J12/K$2 -> 0 | L12: =ROUNDUP(K12,0) -> 0 | M12: =M$2*$C12 -> 0 | N12: =M12/N$2 -> 0 | O12: =ROUNDUP(N12,0) -> 0 | P12: =P$2*$C12 -> 0 | Q12: =P12/Q$2 -> 0 | R12: =ROUNDUP(Q12,0) -> 0 | S12: =S$2*$C12 -> 0 | T12: =S12/T$2 -> 0 | U12: =ROUNDUP(T12,0) -> 0 | Y12: =IFERROR(Y$22*(X12/SUM($X$7:$X$21)), 0) -> 0 | Z12: =Y12*$Z$5 -> 0 | AB12: =IFERROR(X12/$X$22, 0) -> 0
D13: =D$2*$C13 -> 0 | E13: =D13/E$2 -> 0 | F13: =ROUNDUP(E13,0) -> 0 | G13: =G$2*$C13 -> 0 | H13: =G13/H$2 -> 0 | I13: =ROUNDUP(H13,0) -> 0 | J13: =J$2*$C13 -> 0 | K13: =J13/K$2 -> 0 | L13: =ROUNDUP(K13,0) -> 0 | M13: =M$2*$C13 -> 0 | N13: =M13/N$2 -> 0 | O13: =ROUNDUP(N13,0) -> 0 | P13: =P$2*$C13 -> 0 | Q13: =P13/Q$2 -> 0 | R13: =ROUNDUP(Q13,0) -> 0 | S13: =S$2*$C13 -> 0 | T13: =S13/T$2 -> 0 | U13: =ROUNDUP(T13,0) -> 0 | Y13: =IFERROR(Y$22*(X13/SUM($X$7:$X$21)), 0) -> 0 | Z13: =Y13*$Z$5 -> 0 | AB13: =IFERROR(X13/$X$22, 0) -> 0
D14: =D$2*$C14 -> 0 | E14: =D14/E$2 -> 0 | F14: =ROUNDUP(E14,0) -> 0 | G14: =G$2*$C14 -> 0 | H14: =G14/H$2 -> 0 | I14: =ROUNDUP(H14,0) -> 0 | J14: =J$2*$C14 -> 0 | K14: =J14/K$2 -> 0 | L14: =ROUNDUP(K14,0) -> 0 | M14: =M$2*$C14 -> 0 | N14: =M14/N$2 -> 0 | O14: =ROUNDUP(N14,0) -> 0 | P14: =P$2*$C14 -> 0 | Q14: =P14/Q$2 -> 0 | R14: =ROUNDUP(Q14,0) -> 0 | S14: =S$2*$C14 -> 0 | T14: =S14/T$2 -> 0 | U14: =ROUNDUP(T14,0) -> 0 | Y14: =IFERROR(Y$22*(X14/SUM($X$7:$X$21)), 0) -> 0 | Z14: =Y14*$Z$5 -> 0 | AB14: =IFERROR(X14/$X$22, 0) -> 0
D15: =D$2*$C15 -> 0 | E15: =D15/E$2 -> 0 | F15: =ROUNDUP(E15,0) -> 0 | G15: =G$2*$C15 -> 0 | H15: =G15/H$2 -> 0 | I15: =ROUNDUP(H15,0) -> 0 | J15: =J$2*$C15 -> 0 | K15: =J15/K$2 -> 0 | L15: =ROUNDUP(K15,0) -> 0 | M15: =M$2*$C15 -> 0 | N15: =M15/N$2 -> 0 | O15: =ROUNDUP(N15,0) -> 0 | P15: =P$2*$C15 -> 0 | Q15: =P15/Q$2 -> 0 | R15: =ROUNDUP(Q15,0) -> 0 | S15: =S$2*$C15 -> 0 | T15: =S15/T$2 -> 0 | U15: =ROUNDUP(T15,0) -> 0 | Y15: =IFERROR(Y$22*(X15/SUM($X$7:$X$21)), 0) -> 0 | Z15: =Y15*$Z$5 -> 0 | AB15: =IFERROR(X15/$X$22, 0) -> 0
D16: =D$2*$C16 -> 0 | E16: =D16/E$2 -> 0 | F16: =ROUNDUP(E16,0) -> 0 | G16: =G$2*$C16 -> 0 | H16: =G16/H$2 -> 0 | I16: =ROUNDUP(H16,0) -> 0 | J16: =J$2*$C16 -> 0 | K16: =J16/K$2 -> 0 | L16: =ROUNDUP(K16,0) -> 0 | M16: =M$2*$C16 -> 0 | N16: =M16/N$2 -> 0 | O16: =ROUNDUP(N16,0) -> 0 | P16: =P$2*$C16 -> 0 | Q16: =P16/Q$2 -> 0 | R16: =ROUNDUP(Q16,0) -> 0 | S16: =S$2*$C16 -> 0 | T16: =S16/T$2 -> 0 | U16: =ROUNDUP(T16,0) -> 0 | Y16: =IFERROR(Y$22*(X16/SUM($X$7:$X$21)), 0) -> 0 | Z16: =Y16*$Z$5 -> 0 | AB16: =IFERROR(X16/$X$22, 0) -> 0
D17: =D$2*$C17 -> 0 | E17: =D17/E$2 -> 0 | F17: =ROUNDUP(E17,0) -> 0 | G17: =G$2*$C17 -> 0 | H17: =G17/H$2 -> 0 | I17: =ROUNDUP(H17,0) -> 0 | J17: =J$2*$C17 -> 0 | K17: =J17/K$2 -> 0 | L17: =ROUNDUP(K17,0) -> 0 | M17: =M$2*$C17 -> 0 | N17: =M17/N$2 -> 0 | O17: =ROUNDUP(N17,0) -> 0 | P17: =P$2*$C17 -> 0 | Q17: =P17/Q$2 -> 0 | R17: =ROUNDUP(Q17,0) -> 0 | S17: =S$2*$C17 -> 0 | T17: =S17/T$2 -> 0 | U17: =ROUNDUP(T17,0) -> 0 | Y17: =IFERROR(Y$22*(X17/SUM($X$7:$X$21)), 0) -> 0 | Z17: =Y17*$Z$5 -> 0 | AB17: =IFERROR(X17/$X$22, 0) -> 0
D18: =D$2*$C18 -> 0 | E18: =D18/E$2 -> 0 | F18: =ROUNDUP(E18,0) -> 0 | G18: =G$2*$C18 -> 0 | H18: =G18/H$2 -> 0 | I18: =ROUNDUP(H18,0) -> 0 | J18: =J$2*$C18 -> 0 | K18: =J18/K$2 -> 0 | L18: =ROUNDUP(K18,0) -> 0 | M18: =M$2*$C18 -> 0 | N18: =M18/N$2 -> 0 | O18: =ROUNDUP(N18,0) -> 0 | P18: =P$2*$C18 -> 0 | Q18: =P18/Q$2 -> 0 | R18: =ROUNDUP(Q18,0) -> 0 | S18: =S$2*$C18 -> 0 | T18: =S18/T$2 -> 0 | U18: =ROUNDUP(T18,0) -> 0 | Y18: =IFERROR(Y$22*(X18/SUM($X$7:$X$21)), 0) -> 0 | Z18: =Y18*$Z$5 -> 0 | AB18: =IFERROR(X18/$X$22, 0) -> 0
... D21: =D$2*$C21 -> 0 | E21: =D21/E$2 -> 0 | F21: =ROUNDUP(E21,0) -> 0 | G21: =G$2*$C21 -> 0 | H21: =G21/H$2 -> 0 | I21: =ROUNDUP(H21,0) -> 0 | J21: =J$2*$C21 -> 0 | K21: =J21/K$2 -> 0 | L21: =ROUNDUP(K21,0) -> 0 | M21: =M$2*$C21 -> 0 | N21: =M21/N$2 -> 0 | O21: =ROUNDUP(N21,0) -> 0 | P21: =P$2*$C21 -> 0 | Q21: =P21/Q$2 -> 0 | R21: =ROUNDUP(Q21,0) -> 0 | S21: =S$2*$C21 -> 0 | T21: =S21/T$2 -> 0 | U21: =ROUNDUP(T21,0) -> 0 | Y21: =IFERROR(Y$22*(X21/SUM($X$7:$X$21)), 0) -> 0 | Z21: =Y21*$Z$5 -> 0 | AB21: =IFERROR(X21/$X$22, 0) -> 0
D22: =D$2*$C22 -> 0 | E22: =D22/E$2 -> 0 | F22: =ROUNDUP(E22,0) -> 0 | G22: =G$2*$C22 -> 0 | H22: =G22/H$2 -> 0 | I22: =ROUNDUP(H22,0) -> 0 | J22: =J$2*$C22 -> 0 | K22: =J22/K$2 -> 0 | L22: =ROUNDUP(K22,0) -> 0 | M22: =M$2*$C22 -> 0 | N22: =M22/N$2 -> 0 | O22: =ROUNDUP(N22,0) -> 0 | P22: =P$2*$C22 -> 0 | Q22: =P22/Q$2 -> 0 | R22: =ROUNDUP(Q22,0) -> 0 | S22: =S$2*$C22 -> 0 | T22: =S22/T$2 -> 0 | U22: =ROUNDUP(T22,0) -> 0 | X22: =SUM(X7:X21) -> 0 | Y22: =D98 -> 3 | Z22: =Y22*$Z$5 -> 3
D23: =D$2*$C23 -> 0 | E23: =D23/E$2 -> 0 | F23: =ROUNDUP(E23,0) -> 0 | G23: =G$2*$C23 -> 0 | H23: =G23/H$2 -> 0 | I23: =ROUNDUP(H23,0) -> 0 | J23: =J$2*$C23 -> 0 | K23: =J23/K$2 -> 0 | L23: =ROUNDUP(K23,0) -> 0 | M23: =M$2*$C23 -> 0 | N23: =M23/N$2 -> 0 | O23: =ROUNDUP(N23,0) -> 0 | P23: =P$2*$C23 -> 0 | Q23: =P23/Q$2 -> 0 | R23: =ROUNDUP(Q23,0) -> 0 | S23: =S$2*$C23 -> 0 | T23: =S23/T$2 -> 0 | U23: =ROUNDUP(T23,0) -> 0
D24: =D$2*$C24 -> 0 | E24: =D24/E$2 -> 0 | F24: =ROUNDUP(E24,0) -> 0 | G24: =G$2*$C24 -> 0 | H24: =G24/H$2 -> 0 | I24: =ROUNDUP(H24,0) -> 0 | J24: =J$2*$C24 -> 0 | K24: =J24/K$2 -> 0 | L24: =ROUNDUP(K24,0) -> 0 | M24: =M$2*$C24 -> 0 | N24: =M24/N$2 -> 0 | O24: =ROUNDUP(N24,0) -> 0 | P24: =P$2*$C24 -> 0 | Q24: =P24/Q$2 -> 0 | R24: =ROUNDUP(Q24,0) -> 0 | S24: =S$2*$C24 -> 0 | T24: =S24/T$2 -> 0 | U24: =ROUNDUP(T24,0) -> 0
D25: =D$2*$C25 -> 0 | E25: =D25/E$2 -> 0 | F25: =ROUNDUP(E25,0) -> 0 | G25: =G$2*$C25 -> 0 | H25: =G25/H$2 -> 0 | I25: =ROUNDUP(H25,0) -> 0 | J25: =J$2*$C25 -> 0 | K25: =J25/K$2 -> 0 | L25: =ROUNDUP(K25,0) -> 0 | M25: =M$2*$C25 -> 0 | N25: =M25/N$2 -> 0 | O25: =ROUNDUP(N25,0) -> 0 | P25: =P$2*$C25 -> 0 | Q25: =P25/Q$2 -> 0 | R25: =ROUNDUP(Q25,0) -> 0 | S25: =S$2*$C25 -> 0 | T25: =S25/T$2 -> 0 | U25: =ROUNDUP(T25,0) -> 0 | Z25: =Y25*$Z$5 -> 0
D26: =D$2*$C26 -> 0 | E26: =D26/E$2 -> 0 | F26: =ROUNDUP(E26,0) -> 0 | G26: =G$2*$C26 -> 0 | H26: =G26/H$2 -> 0 | I26: =ROUNDUP(H26,0) -> 0 | J26: =J$2*$C26 -> 0 | K26: =J26/K$2 -> 0 | L26: =ROUNDUP(K26,0) -> 0 | M26: =M$2*$C26 -> 0 | N26: =M26/N$2 -> 0 | O26: =ROUNDUP(N26,0) -> 0 | P26: =P$2*$C26 -> 0 | Q26: =P26/Q$2 -> 0 | R26: =ROUNDUP(Q26,0) -> 0 | S26: =S$2*$C26 -> 0 | T26: =S26/T$2 -> 0 | U26: =ROUNDUP(T26,0) -> 0 | Z26: =Y26*$Z$5 -> 0
D27: =D$2*$C27 -> 0 | E27: =D27/E$2 -> 0 | F27: =ROUNDUP(E27,0) -> 0 | G27: =G$2*$C27 -> 0 | H27: =G27/H$2 -> 0 | I27: =ROUNDUP(H27,0) -> 0 | J27: =J$2*$C27 -> 0 | K27: =J27/K$2 -> 0 | L27: =ROUNDUP(K27,0) -> 0 | M27: =M$2*$C27 -> 0 | N27: =M27/N$2 -> 0 | O27: =ROUNDUP(N27,0) -> 0 | P27: =P$2*$C27 -> 0 | Q27: =P27/Q$2 -> 0 | R27: =ROUNDUP(Q27,0) -> 0 | S27: =S$2*$C27 -> 0 | T27: =S27/T$2 -> 0 | U27: =ROUNDUP(T27,0) -> 0 | Z27: =Y27*$Z$5 -> 0
D28: =D$2*$C28 -> 0 | E28: =D28/E$2 -> 0 | F28: =ROUNDUP(E28,0) -> 0 | G28: =G$2*$C28 -> 0 | H28: =G28/H$2 -> 0 | I28: =ROUNDUP(H28,0) -> 0 | J28: =J$2*$C28 -> 0 | K28: =J28/K$2 -> 0 | L28: =ROUNDUP(K28,0) -> 0 | M28: =M$2*$C28 -> 0 | N28: =M28/N$2 -> 0 | O28: =ROUNDUP(N28,0) -> 0 | P28: =P$2*$C28 -> 0 | Q28: =P28/Q$2 -> 0 | R28: =ROUNDUP(Q28,0) -> 0 | S28: =S$2*$C28 -> 0 | T28: =S28/T$2 -> 0 | U28: =ROUNDUP(T28,0) -> 0 | Z28: =Y28*$Z$5 -> 0
D29: =D$2*$C29 -> 0 | E29: =D29/E$2 -> 0 | F29: =ROUNDUP(E29,0) -> 0 | G29: =G$2*$C29 -> 0 | H29: =G29/H$2 -> 0 | I29: =ROUNDUP(H29,0) -> 0 | J29: =J$2*$C29 -> 0 | K29: =J29/K$2 -> 0 | L29: =ROUNDUP(K29,0) -> 0 | M29: =M$2*$C29 -> 0 | N29: =M29/N$2 -> 0 | O29: =ROUNDUP(N29,0) -> 0 | P29: =P$2*$C29 -> 0 | Q29: =P29/Q$2 -> 0 | R29: =ROUNDUP(Q29,0) -> 0 | S29: =S$2*$C29 -> 0 | T29: =S29/T$2 -> 0 | U29: =ROUNDUP(T29,0) -> 0 | Z29: =Y29*$Z$5 -> 0
D30: =D$2*$C30 -> 0 | E30: =D30/E$2 -> 0 | F30: =ROUNDUP(E30,0) -> 0 | G30: =G$2*$C30 -> 0 | H30: =G30/H$2 -> 0 | I30: =ROUNDUP(H30,0) -> 0 | J30: =J$2*$C30 -> 0 | K30: =J30/K$2 -> 0 | L30: =ROUNDUP(K30,0) -> 0 | M30: =M$2*$C30 -> 0 | N30: =M30/N$2 -> 0 | O30: =ROUNDUP(N30,0) -> 0 | P30: =P$2*$C30 -> 0 | Q30: =P30/Q$2 -> 0 | R30: =ROUNDUP(Q30,0) -> 0 | S30: =S$2*$C30 -> 0 | T30: =S30/T$2 -> 0 | U30: =ROUNDUP(T30,0) -> 0 | Z30: =Y30*$Z$5 -> 0
D31: =D$2*$C31 -> 0 | E31: =D31/E$2 -> 0 | F31: =ROUNDUP(E31,0) -> 0 | G31: =G$2*$C31 -> 0 | H31: =G31/H$2 -> 0 | I31: =ROUNDUP(H31,0) -> 0 | J31: =J$2*$C31 -> 0 | K31: =J31/K$2 -> 0 | L31: =ROUNDUP(K31,0) -> 0 | M31: =M$2*$C31 -> 0 | N31: =M31/N$2 -> 0 | O31: =ROUNDUP(N31,0) -> 0 | P31: =P$2*$C31 -> 0 | Q31: =P31/Q$2 -> 0 | R31: =ROUNDUP(Q31,0) -> 0 | S31: =S$2*$C31 -> 0 | T31: =S31/T$2 -> 0 | U31: =ROUNDUP(T31,0) -> 0
D32: =D$2*$C32 -> 0 | E32: =D32/E$2 -> 0 | F32: =ROUNDUP(E32,0) -> 0 | G32: =G$2*$C32 -> 0 | H32: =G32/H$2 -> 0 | I32: =ROUNDUP(H32,0) -> 0 | J32: =J$2*$C32 -> 0 | K32: =J32/K$2 -> 0 | L32: =ROUNDUP(K32,0) -> 0 | M32: =M$2*$C32 -> 0 | N32: =M32/N$2 -> 0 | O32: =ROUNDUP(N32,0) -> 0 | P32: =P$2*$C32 -> 0 | Q32: =P32/Q$2 -> 0 | R32: =ROUNDUP(Q32,0) -> 0 | S32: =S$2*$C32 -> 0 | T32: =S32/T$2 -> 0 | U32: =ROUNDUP(T32,0) -> 0
D33: =D$2*$C33 -> 0 | E33: =D33/E$2 -> 0 | F33: =ROUNDUP(E33,0) -> 0 | G33: =G$2*$C33 -> 0 | H33: =G33/H$2 -> 0 | I33: =ROUNDUP(H33,0) -> 0 | J33: =J$2*$C33 -> 0 | K33: =J33/K$2 -> 0 | L33: =ROUNDUP(K33,0) -> 0 | M33: =M$2*$C33 -> 0 | N33: =M33/N$2 -> 0 | O33: =ROUNDUP(N33,0) -> 0 | P33: =P$2*$C33 -> 0 | Q33: =P33/Q$2 -> 0 | R33: =ROUNDUP(Q33,0) -> 0 | S33: =S$2*$C33 -> 0 | T33: =S33/T$2 -> 0 | U33: =ROUNDUP(T33,0) -> 0
D34: =D$2*$C34 -> 0 | E34: =D34/E$2 -> 0 | F34: =ROUNDUP(E34,0) -> 0 | G34: =G$2*$C34 -> 0 | H34: =G34/H$2 -> 0 | I34: =ROUNDUP(H34,0) -> 0 | J34: =J$2*$C34 -> 0 | K34: =J34/K$2 -> 0 | L34: =ROUNDUP(K34,0) -> 0 | M34: =M$2*$C34 -> 0 | N34: =M34/N$2 -> 0 | O34: =ROUNDUP(N34,0) -> 0 | P34: =P$2*$C34 -> 0 | Q34: =P34/Q$2 -> 0 | R34: =ROUNDUP(Q34,0) -> 0 | S34: =S$2*$C34 -> 0 | T34: =S34/T$2 -> 0 | U34: =ROUNDUP(T34,0) -> 0
D35: =D$2*$C35 -> 0 | E35: =D35/E$2 -> 0 | F35: =ROUNDUP(E35,0) -> 0 | G35: =G$2*$C35 -> 0 | H35: =G35/H$2 -> 0 | I35: =ROUNDUP(H35,0) -> 0 | J35: =J$2*$C35 -> 0 | K35: =J35/K$2 -> 0 | L35: =ROUNDUP(K35,0) -> 0 | M35: =M$2*$C35 -> 0 | N35: =M35/N$2 -> 0 | O35: =ROUNDUP(N35,0) -> 0 | P35: =P$2*$C35 -> 0 | Q35: =P35/Q$2 -> 0 | R35: =ROUNDUP(Q35,0) -> 0 | S35: =S$2*$C35 -> 0 | T35: =S35/T$2 -> 0 | U35: =ROUNDUP(T35,0) -> 0
D36: =D$2*$C36 -> 0 | E36: =D36/E$2 -> 0 | F36: =ROUNDUP(E36,0) -> 0 | G36: =G$2*$C36 -> 0 | H36: =G36/H$2 -> 0 | I36: =ROUNDUP(H36,0) -> 0 | J36: =J$2*$C36 -> 0 | K36: =J36/K$2 -> 0 | L36: =ROUNDUP(K36,0) -> 0 | M36: =M$2*$C36 -> 0 | N36: =M36/N$2 -> 0 | O36: =ROUNDUP(N36,0) -> 0 | P36: =P$2*$C36 -> 0 | Q36: =P36/Q$2 -> 0 | R36: =ROUNDUP(Q36,0) -> 0 | S36: =S$2*$C36 -> 0 | T36: =S36/T$2 -> 0 | U36: =ROUNDUP(T36,0) -> 0
D37: =D$2*$C37 -> 0 | E37: =D37/E$2 -> 0 | F37: =ROUNDUP(E37,0) -> 0 | G37: =G$2*$C37 -> 0 | H37: =G37/H$2 -> 0 | I37: =ROUNDUP(H37,0) -> 0 | J37: =J$2*$C37 -> 0 | K37: =J37/K$2 -> 0 | L37: =ROUNDUP(K37,0) -> 0 | M37: =M$2*$C37 -> 0 | N37: =M37/N$2 -> 0 | O37: =ROUNDUP(N37,0) -> 0 | P37: =P$2*$C37 -> 0 | Q37: =P37/Q$2 -> 0 | R37: =ROUNDUP(Q37,0) -> 0 | S37: =S$2*$C37 -> 0 | T37: =S37/T$2 -> 0 | U37: =ROUNDUP(T37,0) -> 0
D38: =D$2*$C38 -> 0 | E38: =D38/E$2 -> 0 | F38: =ROUNDUP(E38,0) -> 0 | G38: =G$2*$C38 -> 0 | H38: =G38/H$2 -> 0 | I38: =ROUNDUP(H38,0) -> 0 | J38: =J$2*$C38 -> 0 | K38: =J38/K$2 -> 0 | L38: =ROUNDUP(K38,0) -> 0 | M38: =M$2*$C38 -> 0 | N38: =M38/N$2 -> 0 | O38: =ROUNDUP(N38,0) -> 0 | P38: =P$2*$C38 -> 0 | Q38: =P38/Q$2 -> 0 | R38: =ROUNDUP(Q38,0) -> 0 | S38: =S$2*$C38 -> 0 | T38: =S38/T$2 -> 0 | U38: =ROUNDUP(T38,0) -> 0
D39: =D$2*$C39 -> 0 | E39: =D39/E$2 -> 0 | F39: =ROUNDUP(E39,0) -> 0 | G39: =G$2*$C39 -> 0 | H39: =G39/H$2 -> 0 | I39: =ROUNDUP(H39,0) -> 0 | J39: =J$2*$C39 -> 0 | K39: =J39/K$2 -> 0 | L39: =ROUNDUP(K39,0) -> 0 | M39: =M$2*$C39 -> 0 | N39: =M39/N$2 -> 0 | O39: =ROUNDUP(N39,0) -> 0 | P39: =P$2*$C39 -> 0 | Q39: =P39/Q$2 -> 0 | R39: =ROUNDUP(Q39,0) -> 0 | S39: =S$2*$C39 -> 0 | T39: =S39/T$2 -> 0 | U39: =ROUNDUP(T39,0) -> 0
D40: =D$2*$C40 -> 0 | E40: =D40/E$2 -> 0 | F40: =ROUNDUP(E40,0) -> 0 | G40: =G$2*$C40 -> 0 | H40: =G40/H$2 -> 0 | I40: =ROUNDUP(H40,0) -> 0 | J40: =J$2*$C40 -> 0 | K40: =J40/K$2 -> 0 | L40: =ROUNDUP(K40,0) -> 0 | M40: =M$2*$C40 -> 0 | N40: =M40/N$2 -> 0 | O40: =ROUNDUP(N40,0) -> 0 | P40: =P$2*$C40 -> 0 | Q40: =P40/Q$2 -> 0 | R40: =ROUNDUP(Q40,0) -> 0 | S40: =S$2*$C40 -> 0 | T40: =S40/T$2 -> 0 | U40: =ROUNDUP(T40,0) -> 0
D41: =D$2*$C41 -> 0 | E41: =D41/E$2 -> 0 | F41: =ROUNDUP(E41,0) -> 0 | G41: =G$2*$C41 -> 0 | H41: =G41/H$2 -> 0 | I41: =ROUNDUP(H41,0) -> 0 | J41: =J$2*$C41 -> 0 | K41: =J41/K$2 -> 0 | L41: =ROUNDUP(K41,0) -> 0 | M41: =M$2*$C41 -> 0 | N41: =M41/N$2 -> 0 | O41: =ROUNDUP(N41,0) -> 0 | P41: =P$2*$C41 -> 0 | Q41: =P41/Q$2 -> 0 | R41: =ROUNDUP(Q41,0) -> 0 | S41: =S$2*$C41 -> 0 | T41: =S41/T$2 -> 0 | U41: =ROUNDUP(T41,0) -> 0
D42: =D$2*$C42 -> 0 | E42: =D42/E$2 -> 0 | F42: =ROUNDUP(E42,0) -> 0 | G42: =G$2*$C42 -> 0 | H42: =G42/H$2 -> 0 | I42: =ROUNDUP(H42,0) -> 0 | J42: =J$2*$C42 -> 0 | K42: =J42/K$2 -> 0 | L42: =ROUNDUP(K42,0) -> 0 | M42: =M$2*$C42 -> 0 | N42: =M42/N$2 -> 0 | O42: =ROUNDUP(N42,0) -> 0 | P42: =P$2*$C42 -> 0 | Q42: =P42/Q$2 -> 0 | R42: =ROUNDUP(Q42,0) -> 0 | S42: =S$2*$C42 -> 0 | T42: =S42/T$2 -> 0 | U42: =ROUNDUP(T42,0) -> 0
...

Sheet 材料配分
B1: 月 | W1: 月 | Y1: =MAX(計量表!C10:C91) -> 0
B2: 月 | E2: 1000 | H2: 1000 | K2: 1000 | N2: 1000 | Q2: 1000 | T2: 1000
C3: 米(合) | D3: 寿司具(g) | F3: 袋数 | G3: うずら豆 | I3: 袋数 | J3: 錦糸玉子(乾燥) | L3: 袋数 | M3: さくらでんぶ | O3: 袋数 | P3: ゆず酢 | R3: 袋数 | S3: 寿司酢(g) | U3: 袋数 | Y3: =INDEX(計量表!B10:B91, MATCH(材料配分!Y1, 計量表!C10:C91, 0)) -> 0
D4: =D$2*$C4 -> 0 | E4: =D4/E$2 -> 0 | F4: =ROUNDUP(E4,0) -> 0 | G4: =G$2*$C4 -> 0 | H4: =G4/H$2 -> 0 | I4: =ROUNDUP(H4,0) -> 0 | J4: =J$2*$C4 -> 0 | K4: =J4/K$2 -> 0 | L4: =ROUNDUP(K4,0) -> 0 | M4: =M$2*$C4 -> 0 | N4: =M4/N$2 -> 0 | O4: =ROUNDUP(N4,0) -> 0 | P4: =P$2*$C4 -> 0 | Q4: =P4/Q$2 -> 0 | R4: =ROUNDUP(Q4,0) -> 0 | S4: =S$2*$C4 -> 0 | T4: =S4/T$2 -> 0 | U4: =ROUNDUP(T4,0) -> 0 | Y4: =INDEX(計量表!I10:I91, MATCH(材料配分!Y1, 計量表!C10:C91, 0)) -> 0
D5: =D$2*$C5 -> 0 | E5: =D5/E$2 -> 0 | F5: =ROUNDUP(E5,0) -> 0 | G5: =G$2*$C5 -> 0 | H5: =G5/H$2 -> 0 | I5: =ROUNDUP(H5,0) -> 0 | J5: =J$2*$C5 -> 0 | K5: =J5/K$2 -> 0 | L5: =ROUNDUP(K5,0) -> 0 | M5: =M$2*$C5 -> 0 | N5: =M5/N$2 -> 0 | O5: =ROUNDUP(N5,0) -> 0 | P5: =P$2*$C5 -> 0 | Q5: =P5/Q$2 -> 0 | R5: =ROUNDUP(Q5,0) -> 0 | S5: =S$2*$C5 -> 0 | T5: =S5/T$2 -> 0 | U5: =ROUNDUP(T5,0) -> 0 | Y5: =Y3*3/Y4 -> #DIV/0! | AF5: 具材量補正割合 | AG5: 1
D6: =D$2*$C6 -> 0 | E6: =D6/E$2 -> 0 | F6: =ROUNDUP(E6,0) -> 0 | G6: =G$2*$C6 -> 0 | H6: =G6/H$2 -> 0 | I6: =ROUNDUP(H6,0) -> 0 | J6: =J$2*$C6 -> 0 | K6: =J6/K$2 -> 0 | L6: =ROUNDUP(K6,0) -> 0 | M6: =M$2*$C6 -> 0 | N6: =M6/N$2 -> 0 | O6: =ROUNDUP(N6,0) -> 0 | P6: =P$2*$C6 -> 0 | Q6: =P6/Q$2 -> 0 | R6: =ROUNDUP(Q6,0) -> 0 | S6: =S$2*$C6 -> 0 | T6: =S6/T$2 -> 0 | U6: =ROUNDUP(T6,0) -> 0 | W6: 寿司具 | X6: 1人用分量(g) | Y6: 針刺し用 | Z6: 保存用 | AA6: 保存用(合計) | AB6: 1人用*袋数 | AC6: ソフト | AD6: ゼリー | AE6: ミキサー | AF6: 補正なし(g) | AG6: 補正あり(g)
D7: =D$2*$C7 -> 0 | E7: =D7/E$2 -> 0 | F7: =ROUNDUP(E7,0) -> 0 | G7: =G$2*$C7 -> 0 | H7: =G7/H$2 -> 0 | I7: =ROUNDUP(H7,0) -> 0 | J7: =J$2*$C7 -> 0 | K7: =J7/K$2 -> 0 | L7: =ROUNDUP(K7,0) -> 0 | M7: =M$2*$C7 -> 0 | N7: =M7/N$2 -> 0 | O7: =ROUNDUP(N7,0) -> 0 | P7: =P$2*$C7 -> 0 | Q7: =P7/Q$2 -> 0 | R7: =ROUNDUP(Q7,0) -> 0 | S7: =S$2*$C7 -> 0 | T7: =S7/T$2 -> 0 | U7: =ROUNDUP(T7,0) -> 0 | Y7: =IF(X7, X7*$Y$5*合数一覧!$F$92, 0) -> 0 | Z7: =X7*10 -> 0 | AA7: =Z7*5 -> 0 | AB7: =X7*合数一覧!$F$94 -> 0 | AC7: =X7*合数一覧!$C$95 -> 0 | AD7: =X7*合数一覧!$C$96 -> 0 | AE7: =X7*合数一覧!$C$97 -> 0 | AF7: =IF(X7, X7*合数一覧!$C$91*3+SUM(Y7,AA7,AB7,AC7,AD7,AE7), 0) -> 0 | AG7: =AF7*$AG$5 -> 0 | AI7: =IFERROR(X7/$X$22, 0) -> 0
D8: =D$2*$C8 -> 0 | E8: =D8/E$2 -> 0 | F8: =ROUNDUP(E8,0) -> 0 | G8: =G$2*$C8 -> 0 | H8: =G8/H$2 -> 0 | I8: =ROUNDUP(H8,0) -> 0 | J8: =J$2*$C8 -> 0 | K8: =J8/K$2 -> 0 | L8: =ROUNDUP(K8,0) -> 0 | M8: =M$2*$C8 -> 0 | N8: =M8/N$2 -> 0 | O8: =ROUNDUP(N8,0) -> 0 | P8: =P$2*$C8 -> 0 | Q8: =P8/Q$2 -> 0 | R8: =ROUNDUP(Q8,0) -> 0 | S8: =S$2*$C8 -> 0 | T8: =S8/T$2 -> 0 | U8: =ROUNDUP(T8,0) -> 0 | Y8: =IF(X8, X8*$Y$5*合数一覧!$F$92, 0) -> 0 | Z8: =X8*10 -> 0 | AA8: =Z8*5 -> 0 | AB8: =X8*合数一覧!$F$94 -> 0 | AC8: =X8*合数一覧!$C$95 -> 0 | AD8: =X8*合数一覧!$C$96 -> 0 | AE8: =X8*合数一覧!$C$97 -> 0 | AF8: =IF(X8, X8*合数一覧!$C$91*3+SUM(Y8,AA8,AB8,AC8,AD8,AE8), 0) -> 0 | AG8: =AF8*$AG$5 -> 0 | AI8: =IFERROR(X8/$X$22, 0) -> 0
D9: =D$2*$C9 -> 0 | E9: =D9/E$2 -> 0 | F9: =ROUNDUP(E9,0) -> 0 | G9: =G$2*$C9 -> 0 | H9: =G9/H$2 -> 0 | I9: =ROUNDUP(H9,0) -> 0 | J9: =J$2*$C9 -> 0 | K9: =J9/K$2 -> 0 | L9: =ROUNDUP(K9,0) -> 0 | M9: =M$2*$C9 -> 0 | N9: =M9/N$2 -> 0 | O9: =ROUNDUP(N9,0) -> 0 | P9: =P$2*$C9 -> 0 | Q9: =P9/Q$2 -> 0 | R9: =ROUNDUP(Q9,0) -> 0 | S9: =S$2*$C9 -> 0 | T9: =S9/T$2 -> 0 | U9: =ROUNDUP(T9,0) -> 0 | Y9: =IF(X9, X9*$Y$5*合数一覧!$F$92, 0) -> 0 | Z9: =X9*10 -> 0 | AA9: =Z9*5 -> 0 | AB9: =X9*合数一覧!$F$94 -> 0 | AC9: =X9*合数一覧!$C$95 -> 0 | AD9: =X9*合数一覧!$C$96 -> 0 | AE9: =X9*合数一覧!$C$97 -> 0 | AF9: =IF(X9, X9*合数一覧!$C$91*3+SUM(Y9,AA9,AB9,AC9,AD9,AE9), 0) -> 0 | AG9: =AF9*$AG$5 -> 0 | AI9: =IFERROR(X9/$X$22, 0) -> 0
D10: =D$2*$C10 -> 0 | E10: =D10/E$2 -> 0 | F10: =ROUNDUP(E10,0) -> 0 | G10: =G$2*$C10 -> 0 | H10: =G10/H$2 -> 0 | I10: =ROUNDUP(H10,0) -> 0 | J10: =J$2*$C10 -> 0 | K10: =J10/K$2 -> 0 | L10: =ROUNDUP(K10,0) -> 0 | M10: =M$2*$C10 -> 0 | N10: =M10/N$2 -> 0 | O10: =ROUNDUP(N10,0) -> 0 | P10: =P$2*$C10 -> 0 | Q10: =P10/Q$2 -> 0 | R10: =ROUNDUP(Q10,0) -> 0 | S10: =S$2*$C10 -> 0 | T10: =S10/T$2 -> 0 | U10: =ROUNDUP(T10,0) -> 0 | Y10: =IF(X10, X10*$Y$5*合数一覧!$F$92, 0) -> 0 | Z10: =X10*10 -> 0 | AA10: =Z10*5 -> 0 | AB10: =X10*合数一覧!$F$94 -> 0 | AC10: =X10*合数一覧!$C$95 -> 0 | AD10: =X10*合数一覧!$C$96 -> 0 | AE10: =X10*合数一覧!$C$97 -> 0 | AF10: =IF(X10, X10*合数一覧!$C$91*3+SUM(Y10,AA10,AB10,AC10,AD10,AE10), 0) -> 0 | AG10: =AF10*$AG$5 -> 0 | AI10: =IFERROR(X10/$X$22, 0) -> 0
D11: =D$2*$C11 -> 0 | E11: =D11/E$2 -> 0 | F11: =ROUNDUP(E11,0) -> 0 | G11: =G$2*$C11 -> 0 | H11: =G11/H$2 -> 0 | I11: =ROUNDUP(H11,0) -> 0 | J11: =J$2*$C11 -> 0 | K11: =J11/K$2 -> 0 | L11: =ROUNDUP(K11,0) -> 0 | M11: =M$2*$C11 -> 0 | N11: =M11/N$2 -> 0 | O11: =ROUNDUP(N11,0) -> 0 | P11: =P$2*$C11 -> 0 | Q11: =P11/Q$2 -> 0 | R11: =ROUNDUP(Q11,0) -> 0 | S11: =S$2*$C11 -> 0 | T11: =S11/T$2 -> 0 | U11: =ROUNDUP(T11,0) -> 0 | Y11: =IF(X11, X11*$Y$5*合数一覧!$F$92, 0) -> 0 | Z11: =X11*10 -> 0 | AA11: =Z11*5 -> 0 | AB11: =X11*合数一覧!$F$94 -> 0 | AC11: =X11*合数一覧!$C$95 -> 0 | AD11: =X11*合数一覧!$C$96 -> 0 | AE11: =X11*合数一覧!$C$97 -> 0 | AF11: =IF(X11, X11*合数一覧!$C$91*3+SUM(Y11,AA11,AB11,AC11,AD11,AE11), 0) -> 0 | AG11: =AF11*$AG$5 -> 0 | AI11: =IFERROR(X11/$X$22, 0) -> 0
D12: =D$2*$C12 -> 0 | E12: =D12/E$2 -> 0 | F12: =ROUNDUP(E12,0) -> 0 | G12: =G$2*$C12 -> 0 | H12: =G12/H$2 -> 0 | I12: =ROUNDUP(H12,0) -> 0 | J12: =J$2*$C12 -> 0 | K12: =J12/K$2 -> 0 | L12: =ROUNDUP(K12,0) -> 0 | M12: =M$2*$C12 -> 0 | N12: =M12/N$2 -> 0 | O12: =ROUNDUP(N12,0) -> 0 | P12: =P$2*$C12 -> 0 | Q12: =P12/Q$2 -> 0 | R12: =ROUNDUP(Q12,0) -> 0 | S12: =S$2*$C12 -> 0 | T12: =S12/T$2 -> 0 | U12: =ROUNDUP(T12,0) -> 0 | Y12: =IF(X12, X12*$Y$5*合数一覧!$F$92, 0) -> 0 | Z12: =X12*10 -> 0 | AA12: =Z12*5 -> 0 | AB12: =X12*合数一覧!$F$94 -> 0 | AC12: =X12*合数一覧!$C$95 -> 0 | AD12: =X12*合数一覧!$C$96 -> 0 | AE12: =X12*合数一覧!$C$97 -> 0 | AF12: =IF(X12, X12*合数一覧!$C$91*3+SUM(Y12,AA12,AB12,AC12,AD12,AE12), 0) -> 0 | AG12: =AF12*$AG$5 -> 0 | AI12: =IFERROR(X12/$X$22, 0) -> 0
D13: =D$2*$C13 -> 0 | E13: =D13/E$2 -> 0 | F13: =ROUNDUP(E13,0) -> 0 | G13: =G$2*$C13 -> 0 | H13: =G13/H$2 -> 0 | I13: =ROUNDUP(H13,0) -> 0 | J13: =J$2*$C13 -> 0 | K13: =J13/K$2 -> 0 | L13: =ROUNDUP(K13,0) -> 0 | M13: =M$2*$C13 -> 0 | N13: =M13/N$2 -> 0 | O13: =ROUNDUP(N13,0) -> 0 | P13: =P$2*$C13 -> 0 | Q13: =P13/Q$2 -> 0 | R13: =ROUNDUP(Q13,0) -> 0 | S13: =S$2*$C13 -> 0 | T13: =S13/T$2 -> 0 | U13: =ROUNDUP(T13,0) -> 0 | Y13: =IF(X13, X13*$Y$5*合数一覧!$F$92, 0) -> 0 | Z13: =X13*10 -> 0 | AA13: =Z13*5 -> 0 | AB13: =X13*合数一覧!$F$94 -> 0 | AC13: =X13*合数一覧!$C$95 -> 0 | AD13: =X13*合数一覧!$C$96 -> 0 | AE13: =X13*合数一覧!$C$97 -> 0 | AF13: =IF(X13, X13*合数一覧!$C$91*3+SUM(Y13,AA13,AB13,AC13,AD13,AE13), 0) -> 0 | AG13: =AF13*$AG$5 -> 0 | AI13: =IFERROR(X13/$X$22, 0) -> 0
D14: =D$2*$C14 -> 0 | E14: =D14/E$2 -> 0 | F14: =ROUNDUP(E14,0) -> 0 | G14: =G$2*$C14 -> 0 | H14: =G14/H$2 -> 0 | I14: =ROUNDUP(H14,0) -> 0 | J14: =J$2*$C14 -> 0 | K14: =J14/K$2 -> 0 | L14: =ROUNDUP(K14,0) -> 0 | M14: =M$2*$C14 -> 0 | N14: =M14/N$2 -> 0 | O14: =ROUNDUP(N14,0) -> 0 | P14: =P$2*$C14 -> 0 | Q14: =P14/Q$2 -> 0 | R14: =ROUNDUP(Q14,0) -> 0 | S14: =S$2*$C14 -> 0 | T14: =S14/T$2 -> 0 | U14: =ROUNDUP(T14,0) -> 0 | Y14: =IF(X14, X14*$Y$5*合数一覧!$F$92, 0) -> 0 | Z14: =X14*10 -> 0 | AA14: =Z14*5 -> 0 | AB14: =X14*合数一覧!$F$94 -> 0 | AC14: =X14*合数一覧!$C$95 -> 0 | AD14: =X14*合数一覧!$C$96 -> 0 | AE14: =X14*合数一覧!$C$97 -> 0 | AF14: =IF(X14, X14*合数一覧!$C$91*3+SUM(Y14,AA14,AB14,AC14,AD14,AE14), 0) -> 0 | AG14: =AF14*$AG$5 -> 0 | AI14: =IFERROR(X14/$X$22, 0) -> 0
D15: =D$2*$C15 -> 0 | E15: =D15/E$2 -> 0 | F15: =ROUNDUP(E15,0) -> 0 | G15: =G$2*$C15 -> 0 | H15: =G15/H$2 -> 0 | I15: =ROUNDUP(H15,0) -> 0 | J15: =J$2*$C15 -> 0 | K15: =J15/K$2 -> 0 | L15: =ROUNDUP(K15,0) -> 0 | M15: =M$2*$C15 -> 0 | N15: =M15/N$2 -> 0 | O15: =ROUNDUP(N15,0) -> 0 | P15: =P$2*$C15 -> 0 | Q15: =P15/Q$2 -> 0 | R15: =ROUNDUP(Q15,0) -> 0 | S15: =S$2*$C15 -> 0 | T15: =S15/T$2 -> 0 | U15: =ROUNDUP(T15,0) -> 0 | Y15: =IF(X15, X15*$Y$5*合数一覧!$F$92, 0) -> 0 | Z15: =X15*10 -> 0 | AA15: =Z15*5 -> 0 | AB15: =X15*合数一覧!$F$94 -> 0 | AC15: =X15*合数一覧!$C$95 -> 0 | AD15: =X15*合数一覧!$C$96 -> 0 | AE15: =X15*合数一覧!$C$97 -> 0 | AF15: =IF(X15, X15*合数一覧!$C$91*3+SUM(Y15,AA15,AB15,AC15,AD15,AE15), 0) -> 0 | AG15: =AF15*$AG$5 -> 0 | AI15: =IFERROR(X15/$X$22, 0) -> 0
D16: =D$2*$C16 -> 0 | E16: =D16/E$2 -> 0 | F16: =ROUNDUP(E16,0) -> 0 | G16: =G$2*$C16 -> 0 | H16: =G16/H$2 -> 0 | I16: =ROUNDUP(H16,0) -> 0 | J16: =J$2*$C16 -> 0 | K16: =J16/K$2 -> 0 | L16: =ROUNDUP(K16,0) -> 0 | M16: =M$2*$C16 -> 0 | N16: =M16/N$2 -> 0 | O16: =ROUNDUP(N16,0) -> 0 | P16: =P$2*$C16 -> 0 | Q16: =P16/Q$2 -> 0 | R16: =ROUNDUP(Q16,0) -> 0 | S16: =S$2*$C16 -> 0 | T16: =S16/T$2 -> 0 | U16: =ROUNDUP(T16,0) -> 0 | Y16: =IF(X16, X16*$Y$5*合数一覧!$F$92, 0) -> 0 | Z16: =X16*10 -> 0 | AA16: =Z16*5 -> 0 | AB16: =X16*合数一覧!$F$94 -> 0 | AC16: =X16*合数一覧!$C$95 -> 0 | AD16: =X16*合数一覧!$C$96 -> 0 | AE16: =X16*合数一覧!$C$97 -> 0 | AF16: =IF(X16, X16*合数一覧!$C$91*3+SUM(Y16,AA16,AB16,AC16,AD16,AE16), 0) -> 0 | AG16: =AF16*$AG$5 -> 0 | AI16: =IFERROR(X16/$X$22, 0) -> 0
D17: =D$2*$C17 -> 0 | E17: =D17/E$2 -> 0 | F17: =ROUNDUP(E17,0) -> 0 | G17: =G$2*$C17 -> 0 | H17: =G17/H$2 -> 0 | I17: =ROUNDUP(H17,0) -> 0 | J17: =J$2*$C17 -> 0 | K17: =J17/K$2 -> 0 | L17: =ROUNDUP(K17,0) -> 0 | M17: =M$2*$C17 -> 0 | N17: =M17/N$2 -> 0 | O17: =ROUNDUP(N17,0) -> 0 | P17: =P$2*$C17 -> 0 | Q17: =P17/Q$2 -> 0 | R17: =ROUNDUP(Q17,0) -> 0 | S17: =S$2*$C17 -> 0 | T17: =S17/T$2 -> 0 | U17: =ROUNDUP(T17,0) -> 0 | Y17: =IF(X17, X17*$Y$5*合数一覧!$F$92, 0) -> 0 | Z17: =X17*10 -> 0 | AA17: =Z17*5 -> 0 | AB17: =X17*合数一覧!$F$94 -> 0 | AC17: =X17*合数一覧!$C$95 -> 0 | AD17: =X17*合数一覧!$C$96 -> 0 | AE17: =X17*合数一覧!$C$97 -> 0 | AF17: =IF(X17, X17*合数一覧!$C$91*3+SUM(Y17,AA17,AB17,AC17,AD17,AE17), 0) -> 0 | AG17: =AF17*$AG$5 -> 0 | AI17: =IFERROR(X17/$X$22, 0) -> 0
D18: =D$2*$C18 -> 0 | E18: =D18/E$2 -> 0 | F18: =ROUNDUP(E18,0) -> 0 | G18: =G$2*$C18 -> 0 | H18: =G18/H$2 -> 0 | I18: =ROUNDUP(H18,0) -> 0 | J18: =J$2*$C18 -> 0 | K18: =J18/K$2 -> 0 | L18: =ROUNDUP(K18,0) -> 0 | M18: =M$2*$C18 -> 0 | N18: =M18/N$2 -> 0 | O18: =ROUNDUP(N18,0) -> 0 | P18: =P$2*$C18 -> 0 | Q18: =P18/Q$2 -> 0 | R18: =ROUNDUP(Q18,0) -> 0 | S18: =S$2*$C18 -> 0 | T18: =S18/T$2 -> 0 | U18: =ROUNDUP(T18,0) -> 0 | Y18: =IF(X18, X18*$Y$5*合数一覧!$F$92, 0) -> 0 | Z18: =X18*10 -> 0 | AA18: =Z18*5 -> 0 | AB18: =X18*合数一覧!$F$94 -> 0 | AC18: =X18*合数一覧!$C$95 -> 0 | AD18: =X18*合数一覧!$C$96 -> 0 | AE18: =X18*合数一覧!$C$97 -> 0 | AF18: =IF(X18, X18*合数一覧!$C$91*3+SUM(Y18,AA18,AB18,AC18,AD18,AE18), 0) -> 0 | AG18: =AF18*$AG$5 -> 0 | AI18: =IFERROR(X18/$X$22, 0) -> 0
... D21: =D$2*$C21 -> 0 | E21: =D21/E$2 -> 0 | F21: =ROUNDUP(E21,0) -> 0 | G21: =G$2*$C21 -> 0 | H21: =G21/H$2 -> 0 | I21: =ROUNDUP(H21,0) -> 0 | J21: =J$2*$C21 -> 0 | K21: =J21/K$2 -> 0 | L21: =ROUNDUP(K21,0) -> 0 | M21: =M$2*$C21 -> 0 | N21: =M21/N$2 -> 0 | O21: =ROUNDUP(N21,0) -> 0 | P21: =P$2*$C21 -> 0 | Q21: =P21/Q$2 -> 0 | R21: =ROUNDUP(Q21,0) -> 0 | S21: =S$2*$C21 -> 0 | T21: =S21/T$2 -> 0 | U21: =ROUNDUP(T21,0) -> 0 | Y21: =IF(X21, X21*$Y$5*合数一覧!$F$92, 0) -> 0 | Z21: =X21*10 -> 0 | AA21: =Z21*5 -> 0 | AB21: =X21*合数一覧!$F$94 -> 0 | AC21: =X21*合数一覧!$C$95 -> 0 | AD21: =X21*合数一覧!$C$96 -> 0 | AE21: =X21*合数一覧!$C$97 -> 0 | AF21: =IF(X21, X21*合数一覧!$C$91*3+SUM(Y21,AA21,AB21,AC21,AD21,AE21), 0) -> 0 | AG21: =AF21*$AG$5 -> 0 | AI21: =IFERROR(X21/$X$22, 0) -> 0
D22: =D$2*$C22 -> 0 | E22: =D22/E$2 -> 0 | F22: =ROUNDUP(E22,0) -> 0 | G22: =G$2*$C22 -> 0 | H22: =G22/H$2 -> 0 | I22: =ROUNDUP(H22,0) -> 0 | J22: =J$2*$C22 -> 0 | K22: =J22/K$2 -> 0 | L22: =ROUNDUP(K22,0) -> 0 | M22: =M$2*$C22 -> 0 | N22: =M22/N$2 -> 0 | O22: =ROUNDUP(N22,0) -> 0 | P22: =P$2*$C22 -> 0 | Q22: =P22/Q$2 -> 0 | R22: =ROUNDUP(Q22,0) -> 0 | S22: =S$2*$C22 -> 0 | T22: =S22/T$2 -> 0 | U22: =ROUNDUP(T22,0) -> 0 | AF22: =SUM(AF7:AF21) -> 0 | AG22: =AF22*$AG$5 -> 0
D23: =D$2*$C23 -> 0 | E23: =D23/E$2 -> 0 | F23: =ROUNDUP(E23,0) -> 0 | G23: =G$2*$C23 -> 0 | H23: =G23/H$2 -> 0 | I23: =ROUNDUP(H23,0) -> 0 | J23: =J$2*$C23 -> 0 | K23: =J23/K$2 -> 0 | L23: =ROUNDUP(K23,0) -> 0 | M23: =M$2*$C23 -> 0 | N23: =M23/N$2 -> 0 | O23: =ROUNDUP(N23,0) -> 0 | P23: =P$2*$C23 -> 0 | Q23: =P23/Q$2 -> 0 | R23: =ROUNDUP(Q23,0) -> 0 | S23: =S$2*$C23 -> 0 | T23: =S23/T$2 -> 0 | U23: =ROUNDUP(T23,0) -> 0
D24: =D$2*$C24 -> 0 | E24: =D24/E$2 -> 0 | F24: =ROUNDUP(E24,0) -> 0 | G24: =G$2*$C24 -> 0 | H24: =G24/H$2 -> 0 | I24: =ROUNDUP(H24,0) -> 0 | J24: =J$2*$C24 -> 0 | K24: =J24/K$2 -> 0 | L24: =ROUNDUP(K24,0) -> 0 | M24: =M$2*$C24 -> 0 | N24: =M24/N$2 -> 0 | O24: =ROUNDUP(N24,0) -> 0 | P24: =P$2*$C24 -> 0 | Q24: =P24/Q$2 -> 0 | R24: =ROUNDUP(Q24,0) -> 0 | S24: =S$2*$C24 -> 0 | T24: =S24/T$2 -> 0 | U24: =ROUNDUP(T24,0) -> 0
D25: =D$2*$C25 -> 0 | E25: =D25/E$2 -> 0 | F25: =ROUNDUP(E25,0) -> 0 | G25: =G$2*$C25 -> 0 | H25: =G25/H$2 -> 0 | I25: =ROUNDUP(H25,0) -> 0 | J25: =J$2*$C25 -> 0 | K25: =J25/K$2 -> 0 | L25: =ROUNDUP(K25,0) -> 0 | M25: =M$2*$C25 -> 0 | N25: =M25/N$2 -> 0 | O25: =ROUNDUP(N25,0) -> 0 | P25: =P$2*$C25 -> 0 | Q25: =P25/Q$2 -> 0 | R25: =ROUNDUP(Q25,0) -> 0 | S25: =S$2*$C25 -> 0 | T25: =S25/T$2 -> 0 | U25: =ROUNDUP(T25,0) -> 0 | Z25: =X25*10 -> 0 | AA25: =Z25*5 -> 0 | AB25: =X25*合数一覧!$F$94 -> 0 | AC25: =X25*合数一覧!$C$95 -> 0 | AD25: =X25*合数一覧!$C$96 -> 0 | AE25: =X25*合数一覧!$C$97 -> 0 | AF25: =IF(X25, X25*合数一覧!$C$91*3+SUM(Y25,AA25,AB25,AC25,AD25,AE25), 0) -> 0 | AG25: =AF25*$AG$5 -> 0
D26: =D$2*$C26 -> 0 | E26: =D26/E$2 -> 0 | F26: =ROUNDUP(E26,0) -> 0 | G26: =G$2*$C26 -> 0 | H26: =G26/H$2 -> 0 | I26: =ROUNDUP(H26,0) -> 0 | J26: =J$2*$C26 -> 0 | K26: =J26/K$2 -> 0 | L26: =ROUNDUP(K26,0) -> 0 | M26: =M$2*$C26 -> 0 | N26: =M26/N$2 -> 0 | O26: =ROUNDUP(N26,0) -> 0 | P26: =P$2*$C26 -> 0 | Q26: =P26/Q$2 -> 0 | R26: =ROUNDUP(Q26,0) -> 0 | S26: =S$2*$C26 -> 0 | T26: =S26/T$2 -> 0 | U26: =ROUNDUP(T26,0) -> 0 | Z26: =X26*10 -> 0 | AA26: =Z26*5 -> 0 | AB26: =X26*合数一覧!$F$94 -> 0 | AC26: =X26*合数一覧!$C$95 -> 0 | AD26: =X26*合数一覧!$C$96 -> 0 | AE26: =X26*合数一覧!$C$97 -> 0 | AF26: =IF(X26, X26*合数一覧!$C$91*3+SUM(Y26,AA26,AB26,AC26,AD26,AE26), 0) -> 0 | AG26: =AF26*$AG$5 -> 0
D27: =D$2*$C27 -> 0 | E27: =D27/E$2 -> 0 | F27: =ROUNDUP(E27,0) -> 0 | G27: =G$2*$C27 -> 0 | H27: =G27/H$2 -> 0 | I27: =ROUNDUP(H27,0) -> 0 | J27: =J$2*$C27 -> 0 | K27: =J27/K$2 -> 0 | L27: =ROUNDUP(K27,0) -> 0 | M27: =M$2*$C27 -> 0 | N27: =M27/N$2 -> 0 | O27: =ROUNDUP(N27,0) -> 0 | P27: =P$2*$C27 -> 0 | Q27: =P27/Q$2 -> 0 | R27: =ROUNDUP(Q27,0) -> 0 | S27: =S$2*$C27 -> 0 | T27: =S27/T$2 -> 0 | U27: =ROUNDUP(T27,0) -> 0 | Z27: =X27*10 -> 0 | AA27: =Z27*5 -> 0 | AB27: =X27*合数一覧!$F$94 -> 0 | AC27: =X27*合数一覧!$C$95 -> 0 | AD27: =X27*合数一覧!$C$96 -> 0 | AE27: =X27*合数一覧!$C$97 -> 0 | AF27: =IF(X27, X27*合数一覧!$C$91*3+SUM(Y27,AA27,AB27,AC27,AD27,AE27), 0) -> 0 | AG27: =AF27*$AG$5 -> 0
D28: =D$2*$C28 -> 0 | E28: =D28/E$2 -> 0 | F28: =ROUNDUP(E28,0) -> 0 | G28: =G$2*$C28 -> 0 | H28: =G28/H$2 -> 0 | I28: =ROUNDUP(H28,0) -> 0 | J28: =J$2*$C28 -> 0 | K28: =J28/K$2 -> 0 | L28: =ROUNDUP(K28,0) -> 0 | M28: =M$2*$C28 -> 0 | N28: =M28/N$2 -> 0 | O28: =ROUNDUP(N28,0) -> 0 | P28: =P$2*$C28 -> 0 | Q28: =P28/Q$2 -> 0 | R28: =ROUNDUP(Q28,0) -> 0 | S28: =S$2*$C28 -> 0 | T28: =S28/T$2 -> 0 | U28: =ROUNDUP(T28,0) -> 0 | Z28: =X28*10 -> 0 | AA28: =Z28*5 -> 0 | AB28: =X28*合数一覧!$F$94 -> 0 | AC28: =X28*合数一覧!$C$95 -> 0 | AD28: =X28*合数一覧!$C$96 -> 0 | AE28: =X28*合数一覧!$C$97 -> 0 | AF28: =IF(X28, X28*合数一覧!$C$91*3+SUM(Y28,AA28,AB28,AC28,AD28,AE28), 0) -> 0 | AG28: =AF28*$AG$5 -> 0
D29: =D$2*$C29 -> 0 | E29: =D29/E$2 -> 0 | F29: =ROUNDUP(E29,0) -> 0 | G29: =G$2*$C29 -> 0 | H29: =G29/H$2 -> 0 | I29: =ROUNDUP(H29,0) -> 0 | J29: =J$2*$C29 -> 0 | K29: =J29/K$2 -> 0 | L29: =ROUNDUP(K29,0) -> 0 | M29: =M$2*$C29 -> 0 | N29: =M29/N$2 -> 0 | O29: =ROUNDUP(N29,0) -> 0 | P29: =P$2*$C29 -> 0 | Q29: =P29/Q$2 -> 0 | R29: =ROUNDUP(Q29,0) -> 0 | S29: =S$2*$C29 -> 0 | T29: =S29/T$2 -> 0 | U29: =ROUNDUP(T29,0) -> 0 | Z29: =X29*10 -> 0 | AA29: =Z29*5 -> 0 | AB29: =X29*合数一覧!$F$94 -> 0 | AC29: =X29*合数一覧!$C$95 -> 0 | AD29: =X29*合数一覧!$C$96 -> 0 | AE29: =X29*合数一覧!$C$97 -> 0 | AF29: =IF(X29, X29*合数一覧!$C$91*3+SUM(Y29,AA29,AB29,AC29,AD29,AE29), 0) -> 0 | AG29: =AF29*$AG$5 -> 0
D30: =D$2*$C30 -> 0 | E30: =D30/E$2 -> 0 | F30: =ROUNDUP(E30,0) -> 0 | G30: =G$2*$C30 -> 0 | H30: =G30/H$2 -> 0 | I30: =ROUNDUP(H30,0) -> 0 | J30: =J$2*$C30 -> 0 | K30: =J30/K$2 -> 0 | L30: =ROUNDUP(K30,0) -> 0 | M30: =M$2*$C30 -> 0 | N30: =M30/N$2 -> 0 | O30: =ROUNDUP(N30,0) -> 0 | P30: =P$2*$C30 -> 0 | Q30: =P30/Q$2 -> 0 | R30: =ROUNDUP(Q30,0) -> 0 | S30: =S$2*$C30 -> 0 | T30: =S30/T$2 -> 0 | U30: =ROUNDUP(T30,0) -> 0 | Z30: =X30*10 -> 0 | AA30: =Z30*5 -> 0 | AB30: =X30*合数一覧!$F$94 -> 0 | AC30: =X30*合数一覧!$C$95 -> 0 | AD30: =X30*合数一覧!$C$96 -> 0 | AE30: =X30*合数一覧!$C$97 -> 0 | AF30: =IF(X30, X30*合数一覧!$C$91*3+SUM(Y30,AA30,AB30,AC30,AD30,AE30), 0) -> 0 | AG30: =AF30*$AG$5 -> 0
D31: =D$2*$C31 -> 0 | E31: =D31/E$2 -> 0 | F31: =ROUNDUP(E31,0) -> 0 | G31: =G$2*$C31 -> 0 | H31: =G31/H$2 -> 0 | I31: =ROUNDUP(H31,0) -> 0 | J31: =J$2*$C31 -> 0 | K31: =J31/K$2 -> 0 | L31: =ROUNDUP(K31,0) -> 0 | M31: =M$2*$C31 -> 0 | N31: =M31/N$2 -> 0 | O31: =ROUNDUP(N31,0) -> 0 | P31: =P$2*$C31 -> 0 | Q31: =P31/Q$2 -> 0 | R31: =ROUNDUP(Q31,0) -> 0 | S31: =S$2*$C31 -> 0 | T31: =S31/T$2 -> 0 | U31: =ROUNDUP(T31,0) -> 0 | Z31: =X31*10 -> 0 | AA31: =Z31*5 -> 0 | AB31: =X31*合数一覧!$F$94 -> 0 | AC31: =X31*合数一覧!$C$95 -> 0 | AD31: =X31*合数一覧!$C$96 -> 0 | AE31: =X31*合数一覧!$C$97 -> 0 | AF31: =IF(X31, X31*合数一覧!$C$91*3+SUM(Y31,AA31,AB31,AC31,AD31,AE31), 0) -> 0 | AG31: =AF31*$AG$5 -> 0
D32: =D$2*$C32 -> 0 | E32: =D32/E$2 -> 0 | F32: =ROUNDUP(E32,0) -> 0 | G32: =G$2*$C32 -> 0 | H32: =G32/H$2 -> 0 | I32: =ROUNDUP(H32,0) -> 0 | J32: =J$2*$C32 -> 0 | K32: =J32/K$2 -> 0 | L32: =ROUNDUP(K32,0) -> 0 | M32: =M$2*$C32 -> 0 | N32: =M32/N$2 -> 0 | O32: =ROUNDUP(N32,0) -> 0 | P32: =P$2*$C32 -> 0 | Q32: =P32/Q$2 -> 0 | R32: =ROUNDUP(Q32,0) -> 0 | S32: =S$2*$C32 -> 0 | T32: =S32/T$2 -> 0 | U32: =ROUNDUP(T32,0) -> 0 | Z32: =X32*10 -> 0 | AA32: =Z32*5 -> 0 | AB32: =X32*合数一覧!$F$94 -> 0 | AC32: =X32*合数一覧!$C$95 -> 0 | AD32: =X32*合数一覧!$C$96 -> 0 | AE32: =X32*合数一覧!$C$97 -> 0 | AF32: =IF(X32, X32*合数一覧!$C$91*3+SUM(Y32,AA32,AB32,AC32,AD32,AE32), 0) -> 0 | AG32: =AF32*$AG$5 -> 0
D33: =D$2*$C33 -> 0 | E33: =D33/E$2 -> 0 | F33: =ROUNDUP(E33,0) -> 0 | G33: =G$2*$C33 -> 0 | H33: =G33/H$2 -> 0 | I33: =ROUNDUP(H33,0) -> 0 | J33: =J$2*$C33 -> 0 | K33: =J33/K$2 -> 0 | L33: =ROUNDUP(K33,0) -> 0 | M33: =M$2*$C33 -> 0 | N33: =M33/N$2 -> 0 | O33: =ROUNDUP(N33,0) -> 0 | P33: =P$2*$C33 -> 0 | Q33: =P33/Q$2 -> 0 | R33: =ROUNDUP(Q33,0) -> 0 | S33: =S$2*$C33 -> 0 | T33: =S33/T$2 -> 0 | U33: =ROUNDUP(T33,0) -> 0 | Z33: =X33*10 -> 0 | AA33: =Z33*5 -> 0 | AB33: =X33*合数一覧!$F$94 -> 0 | AC33: =X33*合数一覧!$C$95 -> 0 | AD33: =X33*合数一覧!$C$96 -> 0 | AE33: =X33*合数一覧!$C$97 -> 0 | AF33: =IF(X33, X33*合数一覧!$C$91*3+SUM(Y33,AA33,AB33,AC33,AD33,AE33), 0) -> 0 | AG33: =AF33*$AG$5 -> 0
D34: =D$2*$C34 -> 0 | E34: =D34/E$2 -> 0 | F34: =ROUNDUP(E34,0) -> 0 | G34: =G$2*$C34 -> 0 | H34: =G34/H$2 -> 0 | I34: =ROUNDUP(H34,0) -> 0 | J34: =J$2*$C34 -> 0 | K34: =J34/K$2 -> 0 | L34: =ROUNDUP(K34,0) -> 0 | M34: =M$2*$C34 -> 0 | N34: =M34/N$2 -> 0 | O34: =ROUNDUP(N34,0) -> 0 | P34: =P$2*$C34 -> 0 | Q34: =P34/Q$2 -> 0 | R34: =ROUNDUP(Q34,0) -> 0 | S34: =S$2*$C34 -> 0 | T34: =S34/T$2 -> 0 | U34: =ROUNDUP(T34,0) -> 0 | Z34: =X34*10 -> 0 | AA34: =Z34*5 -> 0 | AB34: =X34*合数一覧!$F$94 -> 0 | AC34: =X34*合数一覧!$C$95 -> 0 | AD34: =X34*合数一覧!$C$96 -> 0 | AE34: =X34*合数一覧!$C$97 -> 0 | AF34: =IF(X34, X34*合数一覧!$C$91*3+SUM(Y34,AA34,AB34,AC34,AD34,AE34), 0) -> 0 | AG34: =AF34*$AG$5 -> 0
D35: =D$2*$C35 -> 0 | E35: =D35/E$2 -> 0 | F35: =ROUNDUP(E35,0) -> 0 | G35: =G$2*$C35 -> 0 | H35: =G35/H$2 -> 0 | I35: =ROUNDUP(H35,0) -> 0 | J35: =J$2*$C35 -> 0 | K35: =J35/K$2 -> 0 | L35: =ROUNDUP(K35,0) -> 0 | M35: =M$2*$C35 -> 0 | N35: =M35/N$2 -> 0 | O35: =ROUNDUP(N35,0) -> 0 | P35: =P$2*$C35 -> 0 | Q35: =P35/Q$2 -> 0 | R35: =ROUNDUP(Q35,0) -> 0 | S35: =S$2*$C35 -> 0 | T35: =S35/T$2 -> 0 | U35: =ROUNDUP(T35,0) -> 0 | Z35: =X35*10 -> 0 | AA35: =Z35*5 -> 0 | AB35: =X35*合数一覧!$F$94 -> 0 | AC35: =X35*合数一覧!$C$95 -> 0 | AD35: =X35*合数一覧!$C$96 -> 0 | AE35: =X35*合数一覧!$C$97 -> 0 | AF35: =IF(X35, X35*合数一覧!$C$91*3+SUM(Y35,AA35,AB35,AC35,AD35,AE35), 0) -> 0 | AG35: =AF35*$AG$5 -> 0
D36: =D$2*$C36 -> 0 | E36: =D36/E$2 -> 0 | F36: =ROUNDUP(E36,0) -> 0 | G36: =G$2*$C36 -> 0 | H36: =G36/H$2 -> 0 | I36: =ROUNDUP(H36,0) -> 0 | J36: =J$2*$C36 -> 0 | K36: =J36/K$2 -> 0 | L36: =ROUNDUP(K36,0) -> 0 | M36: =M$2*$C36 -> 0 | N36: =M36/N$2 -> 0 | O36: =ROUNDUP(N36,0) -> 0 | P36: =P$2*$C36 -> 0 | Q36: =P36/Q$2 -> 0 | R36: =ROUNDUP(Q36,0) -> 0 | S36: =S$2*$C36 -> 0 | T36: =S36/T$2 -> 0 | U36: =ROUNDUP(T36,0) -> 0
D37: =D$2*$C37 -> 0 | E37: =D37/E$2 -> 0 | F37: =ROUNDUP(E37,0) -> 0 | G37: =G$2*$C37 -> 0 | H37: =G37/H$2 -> 0 | I37: =ROUNDUP(H37,0) -> 0 | J37: =J$2*$C37 -> 0 | K37: =J37/K$2 -> 0 | L37: =ROUNDUP(K37,0) -> 0 | M37: =M$2*$C37 -> 0 | N37: =M37/N$2 -> 0 | O37: =ROUNDUP(N37,0) -> 0 | P37: =P$2*$C37 -> 0 | Q37: =P37/Q$2 -> 0 | R37: =ROUNDUP(Q37,0) -> 0 | S37: =S$2*$C37 -> 0 | T37: =S37/T$2 -> 0 | U37: =ROUNDUP(T37,0) -> 0
D38: =D$2*$C38 -> 0 | E38: =D38/E$2 -> 0 | F38: =ROUNDUP(E38,0) -> 0 | G38: =G$2*$C38 -> 0 | H38: =G38/H$2 -> 0 | I38: =ROUNDUP(H38,0) -> 0 | J38: =J$2*$C38 -> 0 | K38: =J38/K$2 -> 0 | L38: =ROUNDUP(K38,0) -> 0 | M38: =M$2*$C38 -> 0 | N38: =M38/N$2 -> 0 | O38: =ROUNDUP(N38,0) -> 0 | P38: =P$2*$C38 -> 0 | Q38: =P38/Q$2 -> 0 | R38: =ROUNDUP(Q38,0) -> 0 | S38: =S$2*$C38 -> 0 | T38: =S38/T$2 -> 0 | U38: =ROUNDUP(T38,0) -> 0
D39: =D$2*$C39 -> 0 | E39: =D39/E$2 -> 0 | F39: =ROUNDUP(E39,0) -> 0 | G39: =G$2*$C39 -> 0 | H39: =G39/H$2 -> 0 | I39: =ROUNDUP(H39,0) -> 0 | J39: =J$2*$C39 -> 0 | K39: =J39/K$2 -> 0 | L39: =ROUNDUP(K39,0) -> 0 | M39: =M$2*$C39 -> 0 | N39: =M39/N$2 -> 0 | O39: =ROUNDUP(N39,0) -> 0 | P39: =P$2*$C39 -> 0 | Q39: =P39/Q$2 -> 0 | R39: =ROUNDUP(Q39,0) -> 0 | S39: =S$2*$C39 -> 0 | T39: =S39/T$2 -> 0 | U39: =ROUNDUP(T39,0) -> 0
D40: =D$2*$C40 -> 0 | E40: =D40/E$2 -> 0 | F40: =ROUNDUP(E40,0) -> 0 | G40: =G$2*$C40 -> 0 | H40: =G40/H$2 -> 0 | I40: =ROUNDUP(H40,0) -> 0 | J40: =J$2*$C40 -> 0 | K40: =J40/K$2 -> 0 | L40: =ROUNDUP(K40,0) -> 0 | M40: =M$2*$C40 -> 0 | N40: =M40/N$2 -> 0 | O40: =ROUNDUP(N40,0) -> 0 | P40: =P$2*$C40 -> 0 | Q40: =P40/Q$2 -> 0 | R40: =ROUNDUP(Q40,0) -> 0 | S40: =S$2*$C40 -> 0 | T40: =S40/T$2 -> 0 | U40: =ROUNDUP(T40,0) -> 0
D41: =D$2*$C41 -> 0 | E41: =D41/E$2 -> 0 | F41: =ROUNDUP(E41,0) -> 0 | G41: =G$2*$C41 -> 0 | H41: =G41/H$2 -> 0 | I41: =ROUNDUP(H41,0) -> 0 | J41: =J$2*$C41 -> 0 | K41: =J41/K$2 -> 0 | L41: =ROUNDUP(K41,0) -> 0 | M41: =M$2*$C41 -> 0 | N41: =M41/N$2 -> 0 | O41: =ROUNDUP(N41,0) -> 0 | P41: =P$2*$C41 -> 0 | Q41: =P41/Q$2 -> 0 | R41: =ROUNDUP(Q41,0) -> 0 | S41: =S$2*$C41 -> 0 | T41: =S41/T$2 -> 0 | U41: =ROUNDUP(T41,0) -> 0
D42: =D$2*$C42 -> 0 | E42: =D42/E$2 -> 0 | F42: =ROUNDUP(E42,0) -> 0 | G42: =G$2*$C42 -> 0 | H42: =G42/H$2 -> 0 | I42: =ROUNDUP(H42,0) -> 0 | J42: =J$2*$C42 -> 0 | K42: =J42/K$2 -> 0 | L42: =ROUNDUP(K42,0) -> 0 | M42: =M$2*$C42 -> 0 | N42: =M42/N$2 -> 0 | O42: =ROUNDUP(N42,0) -> 0 | P42: =P$2*$C42 -> 0 | Q42: =P42/Q$2 -> 0 | R42: =ROUNDUP(Q42,0) -> 0 | S42: =S$2*$C42 -> 0 | T42: =S42/T$2 -> 0 | U42: =ROUNDUP(T42,0) -> 0
...

Sheet 計量表
A1: 基本食 | E1: 0.09
A2: =#REF! -> #REF! | C2: 35 | D2: g | E2: =C2*E1 -> 3.15 | F2: g | J2: =#REF! -> #REF! | L2: 8 | M2: ｇ | Q2: =#REF! -> #REF! | S2: 8 | T2: ｇ | X2: =#REF! -> #REF! | Z2: 8 | AA2: ｇ | AE2: =#REF! -> #REF! | AG2: 8 | AH2: ｇ | AL2: =#REF! -> #REF! | AN2: 8 | AO2: ｇ
B3: 合数 | C3: 基本食 | E3: 出汁 | G3: 合計 | I3: 袋数 | K3: 合数 | L3: 基本食 | N3: 合計 | P3: 袋数 | R3: 合数 | S3: 基本食 | U3: 合計 | W3: 袋数 | Y3: 合数 | Z3: 基本食 | AB3: 合計 | AD3: 袋数 | AF3: 合数 | AG3: 基本食 | AI3: 合計 | AK3: 袋数 | AM3: 合数 | AN3: 基本食 | AP3: 合計 | AR3: 袋数
A4: 1人 | B4: 1 | C4: =C2 -> 35 | D4: =D$2 -> g | E4: =C4*E1 -> 3.15 | F4: =F$2 -> g | G4: =(C4+E4) -> 38.15 | H4: =F$2 -> g | J4: 1人 | K4: 1 | L4: =L2 -> 8 | M4: =M$2 -> ｇ | O4: =M$2 -> ｇ | Q4: 1人 | R4: 1 | S4: =S2 -> 8 | T4: =T$2 -> ｇ | V4: =T$2 -> ｇ | X4: 1人 | Y4: 1 | Z4: =Z2 -> 8 | AA4: =AA$2 -> ｇ | AC4: =AA$2 -> ｇ | AE4: 1人 | AF4: 1 | AG4: =AG2 -> 8 | AH4: =AH$2 -> ｇ | AJ4: =AH$2 -> ｇ | AL4: 1人 | AM4: 1 | AN4: =AN2 -> 8 | AO4: =AO$2 -> ｇ | AQ4: =AO$2 -> ｇ
A5: 10人 | B5: 10 | C5: =B5*C2 -> 350 | D5: =D$2 -> g | E5: =C5*E1 -> 31.5 | F5: =F$2 -> g | G5: =(C5+E5) -> 381.5 | H5: =F$2 -> g | J5: 10人 | K5: 10 | L5: =K5*L2 -> 80 | M5: =M$2 -> ｇ | O5: =M$2 -> ｇ | Q5: 10人 | R5: 10 | S5: =R5*S2 -> 80 | T5: =T$2 -> ｇ | V5: =T$2 -> ｇ | X5: 10人 | Y5: 10 | Z5: =Y5*Z2 -> 80 | AA5: =AA$2 -> ｇ | AC5: =AA$2 -> ｇ | AE5: 10人 | AF5: 10 | AG5: =AF5*AG2 -> 80 | AH5: =AH$2 -> ｇ | AJ5: =AH$2 -> ｇ | AL5: 10人 | AM5: 10 | AN5: =AM5*AN2 -> 80 | AO5: =AO$2 -> ｇ | AQ5: =AO$2 -> ｇ
A6: 10人前(針刺し用) | C6: =MAX(C$10:C$92) -> 0 | D6: =D$2 -> g | E6: =IFERROR(C6*E$1, 0) -> 0 | F6: =F$2 -> g | G6: =(C6+E6) -> 0 | H6: =F$2 -> g | I6: 2 | J6: =IF($A6="", "", $A6) -> 10人前(針刺し用) | L6: =MAX(L$10:L$92) -> 0 | M6: =M$2 -> ｇ | O6: =M$2 -> ｇ | P6: 2 | Q6: =IF($A6="", "", $A6) -> 10人前(針刺し用) | S6: =MAX(S$10:S$92) -> 0 | T6: =T$2 -> ｇ | V6: =T$2 -> ｇ | W6: 2 | X6: =IF($A6="", "", $A6) -> 10人前(針刺し用) | Z6: =MAX(Z$10:Z$92) -> 0 | AA6: =AA$2 -> ｇ | AC6: =AA$2 -> ｇ | AD6: 2 | AE6: =IF($A6="", "", $A6) -> 10人前(針刺し用) | AG6: =MAX(AG$10:AG$92) -> 0 | AH6: =AH$2 -> ｇ | AJ6: =AH$2 -> ｇ | AK6: 2 | AL6: =IF($A6="", "", $A6) -> 10人前(針刺し用) | AN6: =MAX(AN$10:AN$70) -> 0 | AO6: =AO$2 -> ｇ | AQ6: =AO$2 -> ｇ
A7: ソフト合計(注文数量) | B7: =合数一覧!$C95 -> 0 | C7: =B7*$C$4 -> 0 | D7: =D$2 -> g | F7: =F$2 -> g | H7: =F$2 -> g | J7: =IF($A7="", "", $A7) -> ソフト合計(注文数量) | K7: =合数一覧!$C95 -> 0 | L7: =合数一覧!G95 -> 0 | M7: =M$2 -> ｇ | O7: =M$2 -> ｇ | Q7: =IF($A7="", "", $A7) -> ソフト合計(注文数量) | R7: =合数一覧!$C95 -> 0 | S7: =合数一覧!J95 -> 0 | T7: =T$2 -> ｇ | V7: =T$2 -> ｇ | X7: =IF($A7="", "", $A7) -> ソフト合計(注文数量) | Y7: =合数一覧!$C95 -> 0 | Z7: =合数一覧!M95 -> 0 | AA7: =AA$2 -> ｇ | AC7: =AA$2 -> ｇ | AE7: =IF($A7="", "", $A7) -> ソフト合計(注文数量) | AF7: =合数一覧!$C95 -> 0 | AG7: =合数一覧!P95 -> 0 | AH7: =AH$2 -> ｇ | AJ7: =AH$2 -> ｇ | AL7: =IF($A7="", "", $A7) -> ソフト合計(注文数量) | AM7: =合数一覧!$C95 -> 0 | AN7: =合数一覧!S95 -> 0 | AO7: =AO$2 -> ｇ | AQ7: =AO$2 -> ｇ
A8: ゼリー合計(注文数量) | B8: =合数一覧!$C96 -> 0 | C8: =B8*$C$4 -> 0 | D8: =D$2 -> g | F8: =F$2 -> g | H8: =F$2 -> g | J8: =IF($A8="", "", $A8) -> ゼリー合計(注文数量) | K8: =合数一覧!$C96 -> 0 | L8: =合数一覧!G96 -> 0 | M8: =M$2 -> ｇ | O8: =M$2 -> ｇ | Q8: =IF($A8="", "", $A8) -> ゼリー合計(注文数量) | R8: =合数一覧!$C96 -> 0 | S8: =合数一覧!J96 -> 0 | T8: =T$2 -> ｇ | V8: =T$2 -> ｇ | X8: =IF($A8="", "", $A8) -> ゼリー合計(注文数量) | Y8: =合数一覧!$C96 -> 0 | Z8: =合数一覧!M96 -> 0 | AA8: =AA$2 -> ｇ | AC8: =AA$2 -> ｇ | AE8: =IF($A8="", "", $A8) -> ゼリー合計(注文数量) | AF8: =合数一覧!$C96 -> 0 | AG8: =合数一覧!P96 -> 0 | AH8: =AH$2 -> ｇ | AJ8: =AH$2 -> ｇ | AL8: =IF($A8="", "", $A8) -> ゼリー合計(注文数量) | AM8: =合数一覧!$C96 -> 0 | AN8: =合数一覧!S96 -> 0 | AO8: =AO$2 -> ｇ | AQ8: =AO$2 -> ｇ
A9: ミキサー合計(注文数量) | B9: =合数一覧!$C97 -> 0 | C9: =B9*$C$4 -> 0 | D9: =D$2 -> g | F9: =F$2 -> g | H9: =F$2 -> g | J9: =IF($A9="", "", $A9) -> ミキサー合計(注文数量) | K9: =合数一覧!$C97 -> 0 | L9: =合数一覧!G97 -> 0 | M9: =M$2 -> ｇ | O9: =M$2 -> ｇ | Q9: =IF($A9="", "", $A9) -> ミキサー合計(注文数量) | R9: =合数一覧!$C97 -> 0 | S9: =合数一覧!J97 -> 0 | T9: =T$2 -> ｇ | V9: =T$2 -> ｇ | X9: =IF($A9="", "", $A9) -> ミキサー合計(注文数量) | Y9: =合数一覧!$C97 -> 0 | Z9: =合数一覧!M97 -> 0 | AA9: =AA$2 -> ｇ | AC9: =AA$2 -> ｇ | AE9: =IF($A9="", "", $A9) -> ミキサー合計(注文数量) | AF9: =合数一覧!$C97 -> 0 | AG9: =合数一覧!P97 -> 0 | AH9: =AH$2 -> ｇ | AJ9: =AH$2 -> ｇ | AL9: =IF($A9="", "", $A9) -> ミキサー合計(注文数量) | AM9: =合数一覧!$C97 -> 0 | AN9: =合数一覧!S97 -> 0 | AO9: =AO$2 -> ｇ | AQ9: =AO$2 -> ｇ
B10: =合数一覧!C4 -> 0 | C10: =IFERROR((合数一覧!D$2*B10)/I10, 0) -> 0 | D10: =D$2 -> g | E10: =IFERROR(C10*E$1, 0) -> 0 | F10: =F$2 -> g | G10: =(C10+E10) -> 0 | H10: =F$2 -> g | I10: =合数一覧!F4 -> 0 | J10: =IF($A10="", "", $A10) | K10: =合数一覧!C4 -> 0 | L10: =IFERROR(合数一覧!G$2*K10/P10, 0) -> 0 | M10: =M$2 -> ｇ | O10: =M$2 -> ｇ | P10: =合数一覧!I4 -> 0 | Q10: =IF($A10="", "", $A10) | R10: =合数一覧!C4 -> 0 | S10: =IFERROR(合数一覧!J$2*R10/W10, 0) -> 0 | T10: =T$2 -> ｇ | V10: =T$2 -> ｇ | W10: =合数一覧!L4 -> 0 | X10: =IF($A10="", "", $A10) | Y10: =合数一覧!C4 -> 0 | Z10: =IFERROR(合数一覧!M$2*Y10/AD10, 0) -> 0 | AA10: =AA$2 -> ｇ | AC10: =AA$2 -> ｇ | AD10: =合数一覧!O4 -> 0 | AE10: =IF($A10="", "", $A10) | AF10: =合数一覧!C4 -> 0 | AG10: =IFERROR(合数一覧!P$2*AF10/AK10, 0) -> 0 | AH10: =AH$2 -> ｇ | AJ10: =AH$2 -> ｇ | AK10: =合数一覧!R4 -> 0 | AL10: =IF($A10="", "", $A10) | AM10: =合数一覧!C4 -> 0 | AN10: =IFERROR(合数一覧!S$2*AM10/AR10, 0) -> 0 | AO10: =AO$2 -> ｇ | AQ10: =AO$2 -> ｇ | AR10: =合数一覧!U4 -> 0
B11: =合数一覧!C5 -> 0 | C11: =IFERROR((合数一覧!D$2*B11)/I11, 0) -> 0 | D11: =D$2 -> g | E11: =IFERROR(C11*E$1, 0) -> 0 | F11: =F$2 -> g | G11: =(C11+E11) -> 0 | H11: =F$2 -> g | I11: =合数一覧!F5 -> 0 | J11: =IF($A11="", "", $A11) | K11: =合数一覧!C5 -> 0 | L11: =IFERROR(合数一覧!G$2*K11/P11, 0) -> 0 | M11: =M$2 -> ｇ | O11: =M$2 -> ｇ | P11: =合数一覧!I5 -> 0 | Q11: =IF($A11="", "", $A11) | R11: =合数一覧!C5 -> 0 | S11: =IFERROR(合数一覧!J$2*R11/W11, 0) -> 0 | T11: =T$2 -> ｇ | V11: =T$2 -> ｇ | W11: =合数一覧!L5 -> 0 | X11: =IF($A11="", "", $A11) | Y11: =合数一覧!C5 -> 0 | Z11: =IFERROR(合数一覧!M$2*Y11/AD11, 0) -> 0 | AA11: =AA$2 -> ｇ | AC11: =AA$2 -> ｇ | AD11: =合数一覧!O5 -> 0 | AE11: =IF($A11="", "", $A11) | AF11: 0 | AG11: =IFERROR(合数一覧!P$2*AF11/AK11, 0) -> 0 | AH11: =AH$2 -> ｇ | AJ11: =AH$2 -> ｇ | AK11: =合数一覧!R5 -> 0 | AL11: =IF($A11="", "", $A11) | AM11: =合数一覧!C5 -> 0 | AN11: =IFERROR(合数一覧!S$2*AM11/AR11, 0) -> 0 | AO11: =AO$2 -> ｇ | AQ11: =AO$2 -> ｇ | AR11: =合数一覧!U5 -> 0
B12: =合数一覧!C6 -> 0 | C12: =IFERROR((合数一覧!D$2*B12)/I12, 0) -> 0 | D12: =D$2 -> g | E12: =IFERROR(C12*E$1, 0) -> 0 | F12: =F$2 -> g | G12: =(C12+E12) -> 0 | H12: =F$2 -> g | I12: =合数一覧!F6 -> 0 | J12: =IF($A12="", "", $A12) | K12: =合数一覧!C6 -> 0 | L12: =IFERROR(合数一覧!G$2*K12/P12, 0) -> 0 | M12: =M$2 -> ｇ | O12: =M$2 -> ｇ | P12: =合数一覧!I6 -> 0 | Q12: =IF($A12="", "", $A12) | R12: =合数一覧!C6 -> 0 | S12: =IFERROR(合数一覧!J$2*R12/W12, 0) -> 0 | T12: =T$2 -> ｇ | V12: =T$2 -> ｇ | W12: =合数一覧!L6 -> 0 | X12: =IF($A12="", "", $A12) | Y12: =合数一覧!C6 -> 0 | Z12: =IFERROR(合数一覧!M$2*Y12/AD12, 0) -> 0 | AA12: =AA$2 -> ｇ | AC12: =AA$2 -> ｇ | AD12: =合数一覧!O6 -> 0 | AE12: =IF($A12="", "", $A12) | AF12: 0 | AG12: =IFERROR(合数一覧!P$2*AF12/AK12, 0) -> 0 | AH12: =AH$2 -> ｇ | AJ12: =AH$2 -> ｇ | AK12: =合数一覧!R6 -> 0 | AL12: =IF($A12="", "", $A12) | AM12: =合数一覧!C6 -> 0 | AN12: =IFERROR(合数一覧!S$2*AM12/AR12, 0) -> 0 | AO12: =AO$2 -> ｇ | AQ12: =AO$2 -> ｇ | AR12: =合数一覧!U6 -> 0
B13: =合数一覧!C7 -> 0 | C13: =IFERROR((合数一覧!D$2*B13)/I13, 0) -> 0 | D13: =D$2 -> g | E13: =IFERROR(C13*E$1, 0) -> 0 | F13: =F$2 -> g | G13: =(C13+E13) -> 0 | H13: =F$2 -> g | I13: =合数一覧!F7 -> 0 | J13: =IF($A13="", "", $A13) | K13: =合数一覧!C7 -> 0 | L13: =IFERROR(合数一覧!G$2*K13/P13, 0) -> 0 | M13: =M$2 -> ｇ | O13: =M$2 -> ｇ | P13: =合数一覧!I7 -> 0 | Q13: =IF($A13="", "", $A13) | R13: =合数一覧!C7 -> 0 | S13: =IFERROR(合数一覧!J$2*R13/W13, 0) -> 0 | T13: =T$2 -> ｇ | V13: =T$2 -> ｇ | W13: =合数一覧!L7 -> 0 | X13: =IF($A13="", "", $A13) | Y13: =合数一覧!C7 -> 0 | Z13: =IFERROR(合数一覧!M$2*Y13/AD13, 0) -> 0 | AA13: =AA$2 -> ｇ | AC13: =AA$2 -> ｇ | AD13: =合数一覧!O7 -> 0 | AE13: =IF($A13="", "", $A13) | AF13: 0 | AG13: =IFERROR(合数一覧!P$2*AF13/AK13, 0) -> 0 | AH13: =AH$2 -> ｇ | AJ13: =AH$2 -> ｇ | AK13: =合数一覧!R7 -> 0 | AL13: =IF($A13="", "", $A13) | AM13: =合数一覧!C7 -> 0 | AN13: =IFERROR(合数一覧!S$2*AM13/AR13, 0) -> 0 | AO13: =AO$2 -> ｇ | AQ13: =AO$2 -> ｇ | AR13: =合数一覧!U7 -> 0
B14: =合数一覧!C8 -> 0 | C14: =IFERROR((合数一覧!D$2*B14)/I14, 0) -> 0 | D14: =D$2 -> g | E14: =IFERROR(C14*E$1, 0) -> 0 | F14: =F$2 -> g | G14: =(C14+E14) -> 0 | H14: =F$2 -> g | I14: =合数一覧!F8 -> 0 | J14: =IF($A14="", "", $A14) | K14: =合数一覧!C8 -> 0 | L14: =IFERROR(合数一覧!G$2*K14/P14, 0) -> 0 | M14: =M$2 -> ｇ | O14: =M$2 -> ｇ | P14: =合数一覧!I8 -> 0 | Q14: =IF($A14="", "", $A14) | R14: =合数一覧!C8 -> 0 | S14: =IFERROR(合数一覧!J$2*R14/W14, 0) -> 0 | T14: =T$2 -> ｇ | V14: =T$2 -> ｇ | W14: =合数一覧!L8 -> 0 | X14: =IF($A14="", "", $A14) | Y14: =合数一覧!C8 -> 0 | Z14: =IFERROR(合数一覧!M$2*Y14/AD14, 0) -> 0 | AA14: =AA$2 -> ｇ | AC14: =AA$2 -> ｇ | AD14: =合数一覧!O8 -> 0 | AE14: =IF($A14="", "", $A14) | AF14: 0 | AG14: =IFERROR(合数一覧!P$2*AF14/AK14, 0) -> 0 | AH14: =AH$2 -> ｇ | AJ14: =AH$2 -> ｇ | AK14: =合数一覧!R8 -> 0 | AL14: =IF($A14="", "", $A14) | AM14: =合数一覧!C8 -> 0 | AN14: =IFERROR(合数一覧!S$2*AM14/AR14, 0) -> 0 | AO14: =AO$2 -> ｇ | AQ14: =AO$2 -> ｇ | AR14: =合数一覧!U8 -> 0
B15: =合数一覧!C9 -> 0 | C15: =IFERROR((合数一覧!D$2*B15)/I15, 0) -> 0 | D15: =D$2 -> g | E15: =IFERROR(C15*E$1, 0) -> 0 | F15: =F$2 -> g | G15: =(C15+E15) -> 0 | H15: =F$2 -> g | I15: =合数一覧!F9 -> 0 | J15: =IF($A15="", "", $A15) | K15: =合数一覧!C9 -> 0 | L15: =IFERROR(合数一覧!G$2*K15/P15, 0) -> 0 | M15: =M$2 -> ｇ | O15: =M$2 -> ｇ | P15: =合数一覧!I9 -> 0 | Q15: =IF($A15="", "", $A15) | R15: =合数一覧!C9 -> 0 | S15: =IFERROR(合数一覧!J$2*R15/W15, 0) -> 0 | T15: =T$2 -> ｇ | V15: =T$2 -> ｇ | W15: =合数一覧!L9 -> 0 | X15: =IF($A15="", "", $A15) | Y15: =合数一覧!C9 -> 0 | Z15: =IFERROR(合数一覧!M$2*Y15/AD15, 0) -> 0 | AA15: =AA$2 -> ｇ | AC15: =AA$2 -> ｇ | AD15: =合数一覧!O9 -> 0 | AE15: =IF($A15="", "", $A15) | AF15: 0 | AG15: =IFERROR(合数一覧!P$2*AF15/AK15, 0) -> 0 | AH15: =AH$2 -> ｇ | AJ15: =AH$2 -> ｇ | AK15: =合数一覧!R9 -> 0 | AL15: =IF($A15="", "", $A15) | AM15: =合数一覧!C9 -> 0 | AN15: =IFERROR(合数一覧!S$2*AM15/AR15, 0) -> 0 | AO15: =AO$2 -> ｇ | AQ15: =AO$2 -> ｇ | AR15: =合数一覧!U9 -> 0
B16: =合数一覧!C10 -> 0 | C16: =IFERROR((合数一覧!D$2*B16)/I16, 0) -> 0 | D16: =D$2 -> g | E16: =IFERROR(C16*E$1, 0) -> 0 | F16: =F$2 -> g | G16: =(C16+E16) -> 0 | H16: =F$2 -> g | I16: =合数一覧!F10 -> 0 | J16: =IF($A16="", "", $A16) | K16: =合数一覧!C10 -> 0 | L16: =IFERROR(合数一覧!G$2*K16/P16, 0) -> 0 | M16: =M$2 -> ｇ | O16: =M$2 -> ｇ | P16: =合数一覧!I10 -> 0 | Q16: =IF($A16="", "", $A16) | R16: =合数一覧!C10 -> 0 | S16: =IFERROR(合数一覧!J$2*R16/W16, 0) -> 0 | T16: =T$2 -> ｇ | V16: =T$2 -> ｇ | W16: =合数一覧!L10 -> 0 | X16: =IF($A16="", "", $A16) | Y16: =合数一覧!C10 -> 0 | Z16: =IFERROR(合数一覧!M$2*Y16/AD16, 0) -> 0 | AA16: =AA$2 -> ｇ | AC16: =AA$2 -> ｇ | AD16: =合数一覧!O10 -> 0 | AE16: =IF($A16="", "", $A16) | AF16: 0 | AG16: =IFERROR(合数一覧!P$2*AF16/AK16, 0) -> 0 | AH16: =AH$2 -> ｇ | AJ16: =AH$2 -> ｇ | AK16: =合数一覧!R10 -> 0 | AL16: =IF($A16="", "", $A16) | AM16: =合数一覧!C10 -> 0 | AN16: =IFERROR(合数一覧!S$2*AM16/AR16, 0) -> 0 | AO16: =AO$2 -> ｇ | AQ16: =AO$2 -> ｇ | AR16: =合数一覧!U10 -> 0
B17: =合数一覧!C11 -> 0 | C17: =IFERROR((合数一覧!D$2*B17)/I17, 0) -> 0 | D17: =D$2 -> g | E17: =IFERROR(C17*E$1, 0) -> 0 | F17: =F$2 -> g | G17: =(C17+E17) -> 0 | H17: =F$2 -> g | I17: =合数一覧!F11 -> 0 | J17: =IF($A17="", "", $A17) | K17: =合数一覧!C11 -> 0 | L17: =IFERROR(合数一覧!G$2*K17/P17, 0) -> 0 | M17: =M$2 -> ｇ | O17: =M$2 -> ｇ | P17: =合数一覧!I11 -> 0 | Q17: =IF($A17="", "", $A17) | R17: =合数一覧!C11 -> 0 | S17: =IFERROR(合数一覧!J$2*R17/W17, 0) -> 0 | T17: =T$2 -> ｇ | V17: =T$2 -> ｇ | W17: =合数一覧!L11 -> 0 | X17: =IF($A17="", "", $A17) | Y17: =合数一覧!C11 -> 0 | Z17: =IFERROR(合数一覧!M$2*Y17/AD17, 0) -> 0 | AA17: =AA$2 -> ｇ | AC17: =AA$2 -> ｇ | AD17: =合数一覧!O11 -> 0 | AE17: =IF($A17="", "", $A17) | AF17: 0 | AG17: =IFERROR(合数一覧!P$2*AF17/AK17, 0) -> 0 | AH17: =AH$2 -> ｇ | AJ17: =AH$2 -> ｇ | AK17: =合数一覧!R11 -> 0 | AL17: =IF($A17="", "", $A17) | AM17: =合数一覧!C11 -> 0 | AN17: =IFERROR(合数一覧!S$2*AM17/AR17, 0) -> 0 | AO17: =AO$2 -> ｇ | AQ17: =AO$2 -> ｇ | AR17: =合数一覧!U11 -> 0
B18: =合数一覧!C12 -> 0 | C18: =IFERROR((合数一覧!D$2*B18)/I18, 0) -> 0 | D18: =D$2 -> g | E18: =IFERROR(C18*E$1, 0) -> 0 | F18: =F$2 -> g | G18: =(C18+E18) -> 0 | H18: =F$2 -> g | I18: =合数一覧!F12 -> 0 | J18: =IF($A18="", "", $A18) | K18: =合数一覧!C12 -> 0 | L18: =IFERROR(合数一覧!G$2*K18/P18, 0) -> 0 | M18: =M$2 -> ｇ | O18: =M$2 -> ｇ | P18: =合数一覧!I12 -> 0 | Q18: =IF($A18="", "", $A18) | R18: =合数一覧!C12 -> 0 | S18: =IFERROR(合数一覧!J$2*R18/W18, 0) -> 0 | T18: =T$2 -> ｇ | V18: =T$2 -> ｇ | W18: =合数一覧!L12 -> 0 | X18: =IF($A18="", "", $A18) | Y18: =合数一覧!C12 -> 0 | Z18: =IFERROR(合数一覧!M$2*Y18/AD18, 0) -> 0 | AA18: =AA$2 -> ｇ | AC18: =AA$2 -> ｇ | AD18: =合数一覧!O12 -> 0 | AE18: =IF($A18="", "", $A18) | AF18: 0 | AG18: =IFERROR(合数一覧!P$2*AF18/AK18, 0) -> 0 | AH18: =AH$2 -> ｇ | AJ18: =AH$2 -> ｇ | AK18: =合数一覧!R12 -> 0 | AL18: =IF($A18="", "", $A18) | AM18: =合数一覧!C12 -> 0 | AN18: =IFERROR(合数一覧!S$2*AM18/AR18, 0) -> 0 | AO18: =AO$2 -> ｇ | AQ18: =AO$2 -> ｇ | AR18: =合数一覧!U12 -> 0
B19: =合数一覧!C13 -> 0 | C19: =IFERROR((合数一覧!D$2*B19)/I19, 0) -> 0 | D19: =D$2 -> g | E19: =IFERROR(C19*E$1, 0) -> 0 | F19: =F$2 -> g | G19: =(C19+E19) -> 0 | H19: =F$2 -> g | I19: =合数一覧!F13 -> 0 | J19: =IF($A19="", "", $A19) | K19: =合数一覧!C13 -> 0 | L19: =IFERROR(合数一覧!G$2*K19/P19, 0) -> 0 | M19: =M$2 -> ｇ | O19: =M$2 -> ｇ | P19: =合数一覧!I13 -> 0 | Q19: =IF($A19="", "", $A19) | R19: =合数一覧!C13 -> 0 | S19: =IFERROR(合数一覧!J$2*R19/W19, 0) -> 0 | T19: =T$2 -> ｇ | V19: =T$2 -> ｇ | W19: =合数一覧!L13 -> 0 | X19: =IF($A19="", "", $A19) | Y19: =合数一覧!C13 -> 0 | Z19: =IFERROR(合数一覧!M$2*Y19/AD19, 0) -> 0 | AA19: =AA$2 -> ｇ | AC19: =AA$2 -> ｇ | AD19: =合数一覧!O13 -> 0 | AE19: =IF($A19="", "", $A19) | AF19: 0 | AG19: =IFERROR(合数一覧!P$2*AF19/AK19, 0) -> 0 | AH19: =AH$2 -> ｇ | AJ19: =AH$2 -> ｇ | AK19: =合数一覧!R13 -> 0 | AL19: =IF($A19="", "", $A19) | AM19: =合数一覧!C13 -> 0 | AN19: =IFERROR(合数一覧!S$2*AM19/AR19, 0) -> 0 | AO19: =AO$2 -> ｇ | AQ19: =AO$2 -> ｇ | AR19: =合数一覧!U13 -> 0
B20: =合数一覧!C14 -> 0 | C20: =IFERROR((合数一覧!D$2*B20)/I20, 0) -> 0 | D20: =D$2 -> g | E20: =IFERROR(C20*E$1, 0) -> 0 | F20: =F$2 -> g | G20: =(C20+E20) -> 0 | H20: =F$2 -> g | I20: =合数一覧!F14 -> 0 | J20: =IF($A20="", "", $A20) | K20: =合数一覧!C14 -> 0 | L20: =IFERROR(合数一覧!G$2*K20/P20, 0) -> 0 | M20: =M$2 -> ｇ | O20: =M$2 -> ｇ | P20: =合数一覧!I14 -> 0 | Q20: =IF($A20="", "", $A20) | R20: =合数一覧!C14 -> 0 | S20: =IFERROR(合数一覧!J$2*R20/W20, 0) -> 0 | T20: =T$2 -> ｇ | V20: =T$2 -> ｇ | W20: =合数一覧!L14 -> 0 | X20: =IF($A20="", "", $A20) | Y20: =合数一覧!C14 -> 0 | Z20: =IFERROR(合数一覧!M$2*Y20/AD20, 0) -> 0 | AA20: =AA$2 -> ｇ | AC20: =AA$2 -> ｇ | AD20: =合数一覧!O14 -> 0 | AE20: =IF($A20="", "", $A20) | AF20: 0 | AG20: =IFERROR(合数一覧!P$2*AF20/AK20, 0) -> 0 | AH20: =AH$2 -> ｇ | AJ20: =AH$2 -> ｇ | AK20: =合数一覧!R14 -> 0 | AL20: =IF($A20="", "", $A20) | AM20: =合数一覧!C14 -> 0 | AN20: =IFERROR(合数一覧!S$2*AM20/AR20, 0) -> 0 | AO20: =AO$2 -> ｇ | AQ20: =AO$2 -> ｇ | AR20: =合数一覧!U14 -> 0
B21: =合数一覧!C15 -> 0 | C21: =IFERROR((合数一覧!D$2*B21)/I21, 0) -> 0 | D21: =D$2 -> g | E21: =IFERROR(C21*E$1, 0) -> 0 | F21: =F$2 -> g | G21: =(C21+E21) -> 0 | H21: =F$2 -> g | I21: =合数一覧!F15 -> 0 | J21: =IF($A21="", "", $A21) | K21: =合数一覧!C15 -> 0 | L21: =IFERROR(合数一覧!G$2*K21/P21, 0) -> 0 | M21: =M$2 -> ｇ | O21: =M$2 -> ｇ | P21: =合数一覧!I15 -> 0 | Q21: =IF($A21="", "", $A21) | R21: =合数一覧!C15 -> 0 | S21: =IFERROR(合数一覧!J$2*R21/W21, 0) -> 0 | T21: =T$2 -> ｇ | V21: =T$2 -> ｇ | W21: =合数一覧!L15 -> 0 | X21: =IF($A21="", "", $A21) | Y21: =合数一覧!C15 -> 0 | Z21: =IFERROR(合数一覧!M$2*Y21/AD21, 0) -> 0 | AA21: =AA$2 -> ｇ | AC21: =AA$2 -> ｇ | AD21: =合数一覧!O15 -> 0 | AE21: =IF($A21="", "", $A21) | AF21: 0 | AG21: =IFERROR(合数一覧!P$2*AF21/AK21, 0) -> 0 | AH21: =AH$2 -> ｇ | AJ21: =AH$2 -> ｇ | AK21: =合数一覧!R15 -> 0 | AL21: =IF($A21="", "", $A21) | AM21: =合数一覧!C15 -> 0 | AN21: =IFERROR(合数一覧!S$2*AM21/AR21, 0) -> 0 | AO21: =AO$2 -> ｇ | AQ21: =AO$2 -> ｇ | AR21: =合数一覧!U15 -> 0
B22: =合数一覧!C16 -> 0 | C22: =IFERROR((合数一覧!D$2*B22)/I22, 0) -> 0 | D22: =D$2 -> g | E22: =IFERROR(C22*E$1, 0) -> 0 | F22: =F$2 -> g | G22: =(C22+E22) -> 0 | H22: =F$2 -> g | I22: =合数一覧!F16 -> 0 | J22: =IF($A22="", "", $A22) | K22: =合数一覧!C16 -> 0 | L22: =IFERROR(合数一覧!G$2*K22/P22, 0) -> 0 | M22: =M$2 -> ｇ | O22: =M$2 -> ｇ | P22: =合数一覧!I16 -> 0 | Q22: =IF($A22="", "", $A22) | R22: =合数一覧!C16 -> 0 | S22: =IFERROR(合数一覧!J$2*R22/W22, 0) -> 0 | T22: =T$2 -> ｇ | V22: =T$2 -> ｇ | W22: =合数一覧!L16 -> 0 | X22: =IF($A22="", "", $A22) | Y22: =合数一覧!C16 -> 0 | Z22: =IFERROR(合数一覧!M$2*Y22/AD22, 0) -> 0 | AA22: =AA$2 -> ｇ | AC22: =AA$2 -> ｇ | AD22: =合数一覧!O16 -> 0 | AE22: =IF($A22="", "", $A22) | AF22: 0 | AG22: =IFERROR(合数一覧!P$2*AF22/AK22, 0) -> 0 | AH22: =AH$2 -> ｇ | AJ22: =AH$2 -> ｇ | AK22: =合数一覧!R16 -> 0 | AL22: =IF($A22="", "", $A22) | AM22: =合数一覧!C16 -> 0 | AN22: =IFERROR(合数一覧!S$2*AM22/AR22, 0) -> 0 | AO22: =AO$2 -> ｇ | AQ22: =AO$2 -> ｇ | AR22: =合数一覧!U16 -> 0
... B91: =合数一覧!C85 -> 0 | C91: =IFERROR((合数一覧!D$2*B91)/I91, 0) -> 0 | D91: =D$2 -> g | E91: =IFERROR(C91*E$1, 0) -> 0 | F91: =F$2 -> g | G91: =(C91+E91) -> 0 | H91: =F$2 -> g | I91: =合数一覧!F85 -> 0 | J91: =IF($A91="", "", $A91) | K91: =合数一覧!C85 -> 0 | L91: =IFERROR(合数一覧!G$2*K91/P91, 0) -> 0 | M91: =M$2 -> ｇ | O91: =M$2 -> ｇ | P91: =合数一覧!I85 -> 0 | Q91: =IF($A91="", "", $A91) | R91: =合数一覧!C85 -> 0 | S91: =IFERROR(合数一覧!J$2*R91/W91, 0) -> 0 | T91: =T$2 -> ｇ | V91: =T$2 -> ｇ | W91: =合数一覧!L85 -> 0 | X91: =IF($A91="", "", $A91) | Y91: =合数一覧!C85 -> 0 | Z91: =IFERROR(合数一覧!M$2*Y91/AD91, 0) -> 0 | AA91: =AA$2 -> ｇ | AC91: =AA$2 -> ｇ | AD91: =合数一覧!O85 -> 0 | AE91: =IF($A91="", "", $A91) | AF91: 0 | AG91: =IFERROR(合数一覧!P$2*AF91/AK91, 0) -> 0 | AH91: =AH$2 -> ｇ | AJ91: =AH$2 -> ｇ | AK91: =合数一覧!R85 -> 0 | AL91: =IF($A91="", "", $A91) | AM91: =合数一覧!C85 -> 0 | AN91: =IFERROR(合数一覧!S$2*AM91/AR91, 0) -> 0 | AO91: =AO$2 -> ｇ | AQ91: =AO$2 -> ｇ | AR91: =合数一覧!U85 -> 0
